Workbook
Name PtsPerWin: SETTINGS!$B$39
Name RatingRange: SETTINGS!$B$36
Name CLOppP0c: CLEAN!$AM$3:$AM$722
Name AsOfDate: SETTINGS!$B$7
Name CalcGP: CALC!$B$2:$B$33
Name MinGamesTrust: SETTINGS!$B$19
Name RatEff: 'TEAM RATINGS'!$J$5:$J$36
Name FavList: LISTS!$B$2:$B$34
Name MktGameID: 'MARKET LINES'!$B$5:$B$304
Name CLGameID: CLEAN!$D$3:$D$722
Name AdjGameID: ADJUSTMENTS!$A$5:$A$104
Name QBSpreadEff: 'QB VALUES'!$G$5:$G$36
Name DQStatus: 'DATA QUALITY'!$P$12:$P$311
Name WinTotalsMode: SETTINGS!$B$40
Name CLPerf: CLEAN!$AE$3:$AE$722
Name BetTot: SETTINGS!$B$29
Name CLOppP1cPv: CLEAN!$AQ$3:$AQ$722
Name CalcOffPl: CALC!$AG$2:$AG$33
Name AdjTeam: ADJUSTMENTS!$B$5:$B$104
Name CLPlays: CLEAN!$Q$3:$Q$722
Name HFAexcTeam: SETTINGS!$A$65:$A$70
Name MktCheck: 'MARKET LINES'!$R$5:$R$304
Name CalcGoverned: CALC!$AD$2:$AD$33
Name PriorEff: PRESEASON!$S$5:$S$36
Name QBStaleDays: SETTINGS!$B$68
Name DQGameID: 'DATA QUALITY'!$B$12:$B$311
Name CLOpp: CLEAN!$K$3:$K$722
Name QBActive: 'QB VALUES'!$D$5:$D$36
Name BlendWts: SETTINGS!$B$44:$B$61
Name WEpa: SETTINGS!$B$12
Name MktHomeSpread: 'MARKET LINES'!$Q$5:$Q$304
Name LeaguePlays: CALC!$B$37
Name TotRegress: SETTINGS!$B$21
Name QBTotEff: 'QB VALUES'!$H$5:$H$36
Name CLOppP2c: CLEAN!$AO$3:$AO$722
Name AdjSpread: ADJUSTMENTS!$E$5:$E$104
Name AdjCap: SETTINGS!$B$34
Name CLOppP1c: CLEAN!$AN$3:$AN$722
Name CLTeam: CLEAN!$I$3:$I$722
Name NeutralHFA: SETTINGS!$B$10
Name MoveCap: SETTINGS!$B$17
Name MktTotal: 'MARKET LINES'!$I$5:$I$304
Name CalcDefAdj: CALC!$AN$2:$AN$33
Name RestCapPts: SETTINGS!$B$16
Name CLUseCur: CLEAN!$AF$3:$AF$722
Name StatsZone: 'IMPORT STATS'!$A$6:$EC$625
Name TotRecency: SETTINGS!$B$22
Name DstPts: CALC!$B$38
Name CLWeek: CLEAN!$G$3:$G$722
Name CLOffPts: CLEAN!$V$3:$V$722
Name MinGamesEnh: SETTINGS!$B$18
Name DQWeek: 'DATA QUALITY'!$C$12:$C$311
Name AdjTot: ADJUSTMENTS!$F$5:$F$104
Name MktStale: 'MARKET LINES'!$S$5:$S$304
Name Teams: LISTS!$A$2:$A$33
Name StatsKey: 'IMPORT STATS'!$EE$6:$EE$625
Name BlendWeeks: SETTINGS!$A$44:$A$61
Name QBTotFactor: SETTINGS!$B$24
Name EngWeek: ENGINE!$C$5:$C$304
Name CLWgtPrev: CLEAN!$AI$3:$AI$722

Sheet START HERE
A1: TO THE WINDOW — NFL POWER RATINGS 2026 (v1.1)
A2: Google Sheets-first · nflverse data in, opponent-adjusted ratings out, Novig lines for edges · no picks sold here, just process
A4: WEEKLY ROUTINE (25-40 min). Status lights update live.
A5: Step | B5: What to do | C5: Status
A6: 1 | B6: Set SETTINGS → Current week + As-of date | C6: =IF(AND(CurrentWeek>=1,CurrentWeek<=22),"OK — week "&CurrentWeek,"⚠ SET WEEK") -> OK — week 1
A7: 2 | B7: Download the two nflverse files (links in DICTIONARY tab) | C7: —
A8: 3 | B8: Paste stats_team_week CSV into IMPORT STATS at A6 (whole file, replaces old) | C8: =IF(CurrentWeek=1,"— (preseason: priors drive ratings)",IF(COUNTIFS(CLWeek,CurrentWeek-1,CLUseCur,1)>=20,"OK — week "&(CurrentWeek-1)&" stats loaded","⚠ WEEK "&(CurrentWeek-1)&" STATS NOT FOUND — REPASTE IMPORT STATS")) -> — (preseason: priors drive ratings)
A9: 4 | B9: Paste games.csv rows for your season(s) into IMPORT SCHEDULE at A6 | C9: =IF(COUNT(SchedSeq)>0,"OK — "&COUNT(SchedSeq)&" games loaded for season "&CurrentSeason,"⚠ NO CURRENT-SEASON GAMES FOUND") -> OK — 272 games loaded for season 2026
A10: 5 | B10: Confirm QB VALUES — active starter, delta, confidence, "Reviewed for season" = current season, fresh update date | C10: =IF(SUMPRODUCT((QBActive="")*1)=0,"OK","⚠ "&SUMPRODUCT((QBActive="")*1)&" TEAMS BLANK") -> OK
A11: 6 | B11: Enter Novig lines in MARKET LINES (favorite + positive spread + total + line date) | C11: ="Missing: "&(SUMPRODUCT((EngWeek=CurrentWeek)*(EngGameID<>"")*1)-SUMPRODUCT((MktHomeSpread<>"")*(EngWeek=CurrentWeek)*1))&" spreads · "&(SUMPRODUCT((EngWeek=CurrentWeek)*(EngGameID<>"")*1)-SUMPRODUCT((MktTotal<>"")*(EngWeek=CurrentWeek)*1))&" totals" -> Missing: 16 spreads · 16 totals
A12: 7 | B12: Log injuries/situational spots in ADJUSTMENTS (explanation required) | C12: —
A13: 8 | B13: Clear DATA QUALITY, then work the DASHBOARD by Review Priority | C13: =IF(SUMPRODUCT((DQStatus="BLOCKED")*(DQWeek=CurrentWeek))=0,"OK — nothing blocked","⚠ "&SUMPRODUCT((DQStatus="BLOCKED")*(DQWeek=CurrentWeek))&" GAME(S) BLOCKED") -> OK — nothing blocked
A15: SIGN CONVENTION — worked example (this trips everyone once)
A16: • Market: Home team favored by 3 → you enter Favorite=HOME, Spread=3 → sheet stores market home spread = -3.0
A17: • Model: FinalMargin = +5.0 (model says home wins by 5) → model spread displays HOME -5.0
A18: • SpreadEdge = FinalMargin + market home spread = 5.0 + (-3.0) = +2.0 → positive = value on HOME at -3.0
A19: • If FinalMargin were +1.0: edge = 1.0 + (-3.0) = -2.0 → negative = value on AWAY at +3.0
A21: TAB MAP
A22: DASHBOARD | B22: This week at a glance, sorted by your attention priority
A23: ENGINE | B23: Every game, every bridge step from ratings to final number
A24: MARKET LINES | B24: Novig entry (favorite + positive spread), OddsLogic reference columns
A25: ADJUSTMENTS | B25: Every subjective point you add, documented and reversible
A26: QB VALUES | B26: Baseline-delta QB system — only deltas move projections
A27: TEAM RATINGS | B27: Final effective ratings + mode + override column
A28: DATA QUALITY | B28: What is blocked and why
A29: SETTINGS | B29: Every weight and threshold, backtest defaults noted
A30: IMPORT tabs | B30: Paste zones for the two nflverse files
A31: Hidden: MAP/CLEAN/CALC | B31: The pipeline — unhide to audit, never edit
A32: Hidden: PRESEASON | B32: Prior blend for season start (2026 priors pre-loaded)
A33: Hidden: HISTORY 2025/BACKTEST/AUDIT/DICTIONARY/CHANGELOG | B33: Receipts: methodology, tests, definitions

Sheet DASHBOARD
A1: WEEKLY DASHBOARD
A2: =CONCATENATE("Season ",CurrentSeason," · Week ",CurrentWeek," · ",TEXT(R3,"0")," games · set week in SETTINGS") -> Season 2026 · Week 1 · 16 games · set week in SETTINGS
A3: ⚠ Labels mark model-vs-market DIVERGENCE thresholds, not proven betting profitability. 2025 was both calibration and evaluation; 2026 is the first out-of-sample test. BET labels are OFF by default (SETTINGS → Enable BET labels). | R3: =SUMPRODUCT((EngWeek=CurrentWeek)*(EngGameID<>"")) -> 16
A4: Game | B4: Date | C4: Market spread | D4: Model spread | E4: Edge (side @ market) | F4: ATS REC | G4: Market total | H4: Model total | I4: O/U edge | J4: TOTAL REC | K4: Total trigger | L4: Status | M4: DQ | N4: Priority | O4: Rank | P4: Mode (A/H) | Q4: Notes
A5: {=IF(IFERROR(MATCH(1,EngDash,0),"")="","",INDEX(ENGINE!$E$5:$E$304,MATCH(1,EngDash,0))&" @ "&INDEX(ENGINE!$F$5:$F$304,MATCH(1,EngDash,0))&IF(INDEX(ENGINE!$G$5:$G$304,MATCH(1,EngDash,0))="Y"," (N)",""))} -> NE @ SEA | B5: {=IF($A5="","",INDEX(ENGINE!$D$5:$D$304,MATCH(1,EngDash,0)))} -> 46274 | C5: {=IF($A5="","",IF(INDEX(ENGINE!$U$5:$U$304,MATCH(1,EngDash,0))="","PENDING",INDEX(ENGINE!$F$5:$F$304,MATCH(1,EngDash,0))&" "&TEXT(INDEX(ENGINE!$U$5:$U$304,MATCH(1,EngDash,0)),"+0.0;-0.0;""PK""")))} -> PENDING | D5: {=IF($A5="","",INDEX(ENGINE!$T$5:$T$304,MATCH(1,EngDash,0)))} -> SEA -3.6 | E5: {=IF($A5="","",IF(INDEX(ENGINE!$V$5:$V$304,MATCH(1,EngDash,0))="","",TEXT(INDEX(ENGINE!$W$5:$W$304,MATCH(1,EngDash,0)),"0.0")&" — "&INDEX(ENGINE!$X$5:$X$304,MATCH(1,EngDash,0))))} | F5: {=IF($A5="","",INDEX(ENGINE!$Z$5:$Z$304,MATCH(1,EngDash,0)))} | G5: {=IF($A5="","",INDEX(ENGINE!$AH$5:$AH$304,MATCH(1,EngDash,0)))} | H5: {=IF($A5="","",INDEX(ENGINE!$AG$5:$AG$304,MATCH(1,EngDash,0)))} -> 0 | I5: {=IF($A5="","",IF(INDEX(ENGINE!$AI$5:$AI$304,MATCH(1,EngDash,0))="","",INDEX(ENGINE!$AK$5:$AK$304,MATCH(1,EngDash,0))&" "&TEXT(INDEX(ENGINE!$AJ$5:$AJ$304,MATCH(1,EngDash,0)),"0.0")))} | J5: {=IF($A5="","",INDEX(ENGINE!$AM$5:$AM$304,MATCH(1,EngDash,0)))} | K5: {=IF($A5="","",INDEX(ENGINE!$AN$5:$AN$304,MATCH(1,EngDash,0)))} -> BET OVER at ≤ -3.0 | BET UNDER at ≥ 3.0 | L5: {=IF($A5="","",INDEX(ENGINE!$AQ$5:$AQ$304,MATCH(1,EngDash,0)))} -> PENDING BOTH | M5: {=IF($A5="","",INDEX(ENGINE!$AP$5:$AP$304,MATCH(1,EngDash,0)))} -> READY | N5: {=IF($A5="","",INDEX(ENGINE!$AS$5:$AS$304,MATCH(1,EngDash,0)))} -> 50 | O5: {=IF($A5="","",INDEX(ENGINE!$AT$5:$AT$304,MATCH(1,EngDash,0)))} -> 1 | P5: {=IF($A5="","",INDEX(RatMode,MATCH(INDEX(ENGINE!$E$5:$E$304,MATCH(1,EngDash,0)),RatTeams,0))&"/"&INDEX(RatMode,MATCH(INDEX(ENGINE!$F$5:$F$304,MATCH(1,EngDash,0)),RatTeams,0)))} -> BASIC/BASIC | Q5: {=IF($A5="","",INDEX(ENGINE!$AU$5:$AU$304,MATCH(1,EngDash,0)))}
A6: {=IF(IFERROR(MATCH(2,EngDash,0),"")="","",INDEX(ENGINE!$E$5:$E$304,MATCH(2,EngDash,0))&" @ "&INDEX(ENGINE!$F$5:$F$304,MATCH(2,EngDash,0))&IF(INDEX(ENGINE!$G$5:$G$304,MATCH(2,EngDash,0))="Y"," (N)",""))} -> SF @ LA (N) | B6: {=IF($A6="","",INDEX(ENGINE!$D$5:$D$304,MATCH(2,EngDash,0)))} -> 46275 | C6: {=IF($A6="","",IF(INDEX(ENGINE!$U$5:$U$304,MATCH(2,EngDash,0))="","PENDING",INDEX(ENGINE!$F$5:$F$304,MATCH(2,EngDash,0))&" "&TEXT(INDEX(ENGINE!$U$5:$U$304,MATCH(2,EngDash,0)),"+0.0;-0.0;""PK""")))} -> PENDING | D6: {=IF($A6="","",INDEX(ENGINE!$T$5:$T$304,MATCH(2,EngDash,0)))} -> LA -2.3 | E6: {=IF($A6="","",IF(INDEX(ENGINE!$V$5:$V$304,MATCH(2,EngDash,0))="","",TEXT(INDEX(ENGINE!$W$5:$W$304,MATCH(2,EngDash,0)),"0.0")&" — "&INDEX(ENGINE!$X$5:$X$304,MATCH(2,EngDash,0))))} | F6: {=IF($A6="","",INDEX(ENGINE!$Z$5:$Z$304,MATCH(2,EngDash,0)))} | G6: {=IF($A6="","",INDEX(ENGINE!$AH$5:$AH$304,MATCH(2,EngDash,0)))} | H6: {=IF($A6="","",INDEX(ENGINE!$AG$5:$AG$304,MATCH(2,EngDash,0)))} -> 0 | I6: {=IF($A6="","",IF(INDEX(ENGINE!$AI$5:$AI$304,MATCH(2,EngDash,0))="","",INDEX(ENGINE!$AK$5:$AK$304,MATCH(2,EngDash,0))&" "&TEXT(INDEX(ENGINE!$AJ$5:$AJ$304,MATCH(2,EngDash,0)),"0.0")))} | J6: {=IF($A6="","",INDEX(ENGINE!$AM$5:$AM$304,MATCH(2,EngDash,0)))} | K6: {=IF($A6="","",INDEX(ENGINE!$AN$5:$AN$304,MATCH(2,EngDash,0)))} -> BET OVER at ≤ -3.0 | BET UNDER at ≥ 3.0 | L6: {=IF($A6="","",INDEX(ENGINE!$AQ$5:$AQ$304,MATCH(2,EngDash,0)))} -> PENDING BOTH | M6: {=IF($A6="","",INDEX(ENGINE!$AP$5:$AP$304,MATCH(2,EngDash,0)))} -> READY | N6: {=IF($A6="","",INDEX(ENGINE!$AS$5:$AS$304,MATCH(2,EngDash,0)))} -> 50 | O6: {=IF($A6="","",INDEX(ENGINE!$AT$5:$AT$304,MATCH(2,EngDash,0)))} -> 1 | P6: {=IF($A6="","",INDEX(RatMode,MATCH(INDEX(ENGINE!$E$5:$E$304,MATCH(2,EngDash,0)),RatTeams,0))&"/"&INDEX(RatMode,MATCH(INDEX(ENGINE!$F$5:$F$304,MATCH(2,EngDash,0)),RatTeams,0)))} -> BASIC/BASIC | Q6: {=IF($A6="","",INDEX(ENGINE!$AU$5:$AU$304,MATCH(2,EngDash,0)))}
A7: {=IF(IFERROR(MATCH(3,EngDash,0),"")="","",INDEX(ENGINE!$E$5:$E$304,MATCH(3,EngDash,0))&" @ "&INDEX(ENGINE!$F$5:$F$304,MATCH(3,EngDash,0))&IF(INDEX(ENGINE!$G$5:$G$304,MATCH(3,EngDash,0))="Y"," (N)",""))} -> CHI @ CAR | B7: {=IF($A7="","",INDEX(ENGINE!$D$5:$D$304,MATCH(3,EngDash,0)))} -> 46278 | C7: {=IF($A7="","",IF(INDEX(ENGINE!$U$5:$U$304,MATCH(3,EngDash,0))="","PENDING",INDEX(ENGINE!$F$5:$F$304,MATCH(3,EngDash,0))&" "&TEXT(INDEX(ENGINE!$U$5:$U$304,MATCH(3,EngDash,0)),"+0.0;-0.0;""PK""")))} -> PENDING | D7: {=IF($A7="","",INDEX(ENGINE!$T$5:$T$304,MATCH(3,EngDash,0)))} -> CHI -0.6 | E7: {=IF($A7="","",IF(INDEX(ENGINE!$V$5:$V$304,MATCH(3,EngDash,0))="","",TEXT(INDEX(ENGINE!$W$5:$W$304,MATCH(3,EngDash,0)),"0.0")&" — "&INDEX(ENGINE!$X$5:$X$304,MATCH(3,EngDash,0))))} | F7: {=IF($A7="","",INDEX(ENGINE!$Z$5:$Z$304,MATCH(3,EngDash,0)))} | G7: {=IF($A7="","",INDEX(ENGINE!$AH$5:$AH$304,MATCH(3,EngDash,0)))} | H7: {=IF($A7="","",INDEX(ENGINE!$AG$5:$AG$304,MATCH(3,EngDash,0)))} -> 0 | I7: {=IF($A7="","",IF(INDEX(ENGINE!$AI$5:$AI$304,MATCH(3,EngDash,0))="","",INDEX(ENGINE!$AK$5:$AK$304,MATCH(3,EngDash,0))&" "&TEXT(INDEX(ENGINE!$AJ$5:$AJ$304,MATCH(3,EngDash,0)),"0.0")))} | J7: {=IF($A7="","",INDEX(ENGINE!$AM$5:$AM$304,MATCH(3,EngDash,0)))} | K7: {=IF($A7="","",INDEX(ENGINE!$AN$5:$AN$304,MATCH(3,EngDash,0)))} -> BET OVER at ≤ -3.0 | BET UNDER at ≥ 3.0 | L7: {=IF($A7="","",INDEX(ENGINE!$AQ$5:$AQ$304,MATCH(3,EngDash,0)))} -> PENDING BOTH | M7: {=IF($A7="","",INDEX(ENGINE!$AP$5:$AP$304,MATCH(3,EngDash,0)))} -> READY | N7: {=IF($A7="","",INDEX(ENGINE!$AS$5:$AS$304,MATCH(3,EngDash,0)))} -> 50 | O7: {=IF($A7="","",INDEX(ENGINE!$AT$5:$AT$304,MATCH(3,EngDash,0)))} -> 1 | P7: {=IF($A7="","",INDEX(RatMode,MATCH(INDEX(ENGINE!$E$5:$E$304,MATCH(3,EngDash,0)),RatTeams,0))&"/"&INDEX(RatMode,MATCH(INDEX(ENGINE!$F$5:$F$304,MATCH(3,EngDash,0)),RatTeams,0)))} -> BASIC/BASIC | Q7: {=IF($A7="","",INDEX(ENGINE!$AU$5:$AU$304,MATCH(3,EngDash,0)))}
A8: {=IF(IFERROR(MATCH(4,EngDash,0),"")="","",INDEX(ENGINE!$E$5:$E$304,MATCH(4,EngDash,0))&" @ "&INDEX(ENGINE!$F$5:$F$304,MATCH(4,EngDash,0))&IF(INDEX(ENGINE!$G$5:$G$304,MATCH(4,EngDash,0))="Y"," (N)",""))} -> TB @ CIN | B8: {=IF($A8="","",INDEX(ENGINE!$D$5:$D$304,MATCH(4,EngDash,0)))} -> 46278 | C8: {=IF($A8="","",IF(INDEX(ENGINE!$U$5:$U$304,MATCH(4,EngDash,0))="","PENDING",INDEX(ENGINE!$F$5:$F$304,MATCH(4,EngDash,0))&" "&TEXT(INDEX(ENGINE!$U$5:$U$304,MATCH(4,EngDash,0)),"+0.0;-0.0;""PK""")))} -> PENDING | D8: {=IF($A8="","",INDEX(ENGINE!$T$5:$T$304,MATCH(4,EngDash,0)))} -> CIN -0.6 | E8: {=IF($A8="","",IF(INDEX(ENGINE!$V$5:$V$304,MATCH(4,EngDash,0))="","",TEXT(INDEX(ENGINE!$W$5:$W$304,MATCH(4,EngDash,0)),"0.0")&" — "&INDEX(ENGINE!$X$5:$X$304,MATCH(4,EngDash,0))))} | F8: {=IF($A8="","",INDEX(ENGINE!$Z$5:$Z$304,MATCH(4,EngDash,0)))} | G8: {=IF($A8="","",INDEX(ENGINE!$AH$5:$AH$304,MATCH(4,EngDash,0)))} | H8: {=IF($A8="","",INDEX(ENGINE!$AG$5:$AG$304,MATCH(4,EngDash,0)))} -> 0 | I8: {=IF($A8="","",IF(INDEX(ENGINE!$AI$5:$AI$304,MATCH(4,EngDash,0))="","",INDEX(ENGINE!$AK$5:$AK$304,MATCH(4,EngDash,0))&" "&TEXT(INDEX(ENGINE!$AJ$5:$AJ$304,MATCH(4,EngDash,0)),"0.0")))} | J8: {=IF($A8="","",INDEX(ENGINE!$AM$5:$AM$304,MATCH(4,EngDash,0)))} | K8: {=IF($A8="","",INDEX(ENGINE!$AN$5:$AN$304,MATCH(4,EngDash,0)))} -> BET OVER at ≤ -3.0 | BET UNDER at ≥ 3.0 | L8: {=IF($A8="","",INDEX(ENGINE!$AQ$5:$AQ$304,MATCH(4,EngDash,0)))} -> PENDING BOTH | M8: {=IF($A8="","",INDEX(ENGINE!$AP$5:$AP$304,MATCH(4,EngDash,0)))} -> READY | N8: {=IF($A8="","",INDEX(ENGINE!$AS$5:$AS$304,MATCH(4,EngDash,0)))} -> 50 | O8: {=IF($A8="","",INDEX(ENGINE!$AT$5:$AT$304,MATCH(4,EngDash,0)))} -> 1 | P8: {=IF($A8="","",INDEX(RatMode,MATCH(INDEX(ENGINE!$E$5:$E$304,MATCH(4,EngDash,0)),RatTeams,0))&"/"&INDEX(RatMode,MATCH(INDEX(ENGINE!$F$5:$F$304,MATCH(4,EngDash,0)),RatTeams,0)))} -> BASIC/BASIC | Q8: {=IF($A8="","",INDEX(ENGINE!$AU$5:$AU$304,MATCH(4,EngDash,0)))}
A9: {=IF(IFERROR(MATCH(5,EngDash,0),"")="","",INDEX(ENGINE!$E$5:$E$304,MATCH(5,EngDash,0))&" @ "&INDEX(ENGINE!$F$5:$F$304,MATCH(5,EngDash,0))&IF(INDEX(ENGINE!$G$5:$G$304,MATCH(5,EngDash,0))="Y"," (N)",""))} -> NO @ DET | B9: {=IF($A9="","",INDEX(ENGINE!$D$5:$D$304,MATCH(5,EngDash,0)))} -> 46278 | C9: {=IF($A9="","",IF(INDEX(ENGINE!$U$5:$U$304,MATCH(5,EngDash,0))="","PENDING",INDEX(ENGINE!$F$5:$F$304,MATCH(5,EngDash,0))&" "&TEXT(INDEX(ENGINE!$U$5:$U$304,MATCH(5,EngDash,0)),"+0.0;-0.0;""PK""")))} -> PENDING | D9: {=IF($A9="","",INDEX(ENGINE!$T$5:$T$304,MATCH(5,EngDash,0)))} -> DET -3.4 | E9: {=IF($A9="","",IF(INDEX(ENGINE!$V$5:$V$304,MATCH(5,EngDash,0))="","",TEXT(INDEX(ENGINE!$W$5:$W$304,MATCH(5,EngDash,0)),"0.0")&" — "&INDEX(ENGINE!$X$5:$X$304,MATCH(5,EngDash,0))))} | F9: {=IF($A9="","",INDEX(ENGINE!$Z$5:$Z$304,MATCH(5,EngDash,0)))} | G9: {=IF($A9="","",INDEX(ENGINE!$AH$5:$AH$304,MATCH(5,EngDash,0)))} | H9: {=IF($A9="","",INDEX(ENGINE!$AG$5:$AG$304,MATCH(5,EngDash,0)))} -> 0 | I9: {=IF($A9="","",IF(INDEX(ENGINE!$AI$5:$AI$304,MATCH(5,EngDash,0))="","",INDEX(ENGINE!$AK$5:$AK$304,MATCH(5,EngDash,0))&" "&TEXT(INDEX(ENGINE!$AJ$5:$AJ$304,MATCH(5,EngDash,0)),"0.0")))} | J9: {=IF($A9="","",INDEX(ENGINE!$AM$5:$AM$304,MATCH(5,EngDash,0)))} | K9: {=IF($A9="","",INDEX(ENGINE!$AN$5:$AN$304,MATCH(5,EngDash,0)))} -> BET OVER at ≤ -3.0 | BET UNDER at ≥ 3.0 | L9: {=IF($A9="","",INDEX(ENGINE!$AQ$5:$AQ$304,MATCH(5,EngDash,0)))} -> PENDING BOTH | M9: {=IF($A9="","",INDEX(ENGINE!$AP$5:$AP$304,MATCH(5,EngDash,0)))} -> READY | N9: {=IF($A9="","",INDEX(ENGINE!$AS$5:$AS$304,MATCH(5,EngDash,0)))} -> 50 | O9: {=IF($A9="","",INDEX(ENGINE!$AT$5:$AT$304,MATCH(5,EngDash,0)))} -> 1 | P9: {=IF($A9="","",INDEX(RatMode,MATCH(INDEX(ENGINE!$E$5:$E$304,MATCH(5,EngDash,0)),RatTeams,0))&"/"&INDEX(RatMode,MATCH(INDEX(ENGINE!$F$5:$F$304,MATCH(5,EngDash,0)),RatTeams,0)))} -> BASIC/BASIC | Q9: {=IF($A9="","",INDEX(ENGINE!$AU$5:$AU$304,MATCH(5,EngDash,0)))}
A10: {=IF(IFERROR(MATCH(6,EngDash,0),"")="","",INDEX(ENGINE!$E$5:$E$304,MATCH(6,EngDash,0))&" @ "&INDEX(ENGINE!$F$5:$F$304,MATCH(6,EngDash,0))&IF(INDEX(ENGINE!$G$5:$G$304,MATCH(6,EngDash,0))="Y"," (N)",""))} -> BUF @ HOU | B10: {=IF($A10="","",INDEX(ENGINE!$D$5:$D$304,MATCH(6,EngDash,0)))} -> 46278 | C10: {=IF($A10="","",IF(INDEX(ENGINE!$U$5:$U$304,MATCH(6,EngDash,0))="","PENDING",INDEX(ENGINE!$F$5:$F$304,MATCH(6,EngDash,0))&" "&TEXT(INDEX(ENGINE!$U$5:$U$304,MATCH(6,EngDash,0)),"+0.0;-0.0;""PK""")))} -> PENDING | D10: {=IF($A10="","",INDEX(ENGINE!$T$5:$T$304,MATCH(6,EngDash,0)))} -> HOU -2.6 | E10: {=IF($A10="","",IF(INDEX(ENGINE!$V$5:$V$304,MATCH(6,EngDash,0))="","",TEXT(INDEX(ENGINE!$W$5:$W$304,MATCH(6,EngDash,0)),"0.0")&" — "&INDEX(ENGINE!$X$5:$X$304,MATCH(6,EngDash,0))))} | F10: {=IF($A10="","",INDEX(ENGINE!$Z$5:$Z$304,MATCH(6,EngDash,0)))} | G10: {=IF($A10="","",INDEX(ENGINE!$AH$5:$AH$304,MATCH(6,EngDash,0)))} | H10: {=IF($A10="","",INDEX(ENGINE!$AG$5:$AG$304,MATCH(6,EngDash,0)))} -> 0 | I10: {=IF($A10="","",IF(INDEX(ENGINE!$AI$5:$AI$304,MATCH(6,EngDash,0))="","",INDEX(ENGINE!$AK$5:$AK$304,MATCH(6,EngDash,0))&" "&TEXT(INDEX(ENGINE!$AJ$5:$AJ$304,MATCH(6,EngDash,0)),"0.0")))} | J10: {=IF($A10="","",INDEX(ENGINE!$AM$5:$AM$304,MATCH(6,EngDash,0)))} | K10: {=IF($A10="","",INDEX(ENGINE!$AN$5:$AN$304,MATCH(6,EngDash,0)))} -> BET OVER at ≤ -3.0 | BET UNDER at ≥ 3.0 | L10: {=IF($A10="","",INDEX(ENGINE!$AQ$5:$AQ$304,MATCH(6,EngDash,0)))} -> PENDING BOTH | M10: {=IF($A10="","",INDEX(ENGINE!$AP$5:$AP$304,MATCH(6,EngDash,0)))} -> READY | N10: {=IF($A10="","",INDEX(ENGINE!$AS$5:$AS$304,MATCH(6,EngDash,0)))} -> 50 | O10: {=IF($A10="","",INDEX(ENGINE!$AT$5:$AT$304,MATCH(6,EngDash,0)))} -> 1 | P10: {=IF($A10="","",INDEX(RatMode,MATCH(INDEX(ENGINE!$E$5:$E$304,MATCH(6,EngDash,0)),RatTeams,0))&"/"&INDEX(RatMode,MATCH(INDEX(ENGINE!$F$5:$F$304,MATCH(6,EngDash,0)),RatTeams,0)))} -> BASIC/BASIC | Q10: {=IF($A10="","",INDEX(ENGINE!$AU$5:$AU$304,MATCH(6,EngDash,0)))}
A11: {=IF(IFERROR(MATCH(7,EngDash,0),"")="","",INDEX(ENGINE!$E$5:$E$304,MATCH(7,EngDash,0))&" @ "&INDEX(ENGINE!$F$5:$F$304,MATCH(7,EngDash,0))&IF(INDEX(ENGINE!$G$5:$G$304,MATCH(7,EngDash,0))="Y"," (N)",""))} -> BAL @ IND | B11: {=IF($A11="","",INDEX(ENGINE!$D$5:$D$304,MATCH(7,EngDash,0)))} -> 46278 | C11: {=IF($A11="","",IF(INDEX(ENGINE!$U$5:$U$304,MATCH(7,EngDash,0))="","PENDING",INDEX(ENGINE!$F$5:$F$304,MATCH(7,EngDash,0))&" "&TEXT(INDEX(ENGINE!$U$5:$U$304,MATCH(7,EngDash,0)),"+0.0;-0.0;""PK""")))} -> PENDING | D11: {=IF($A11="","",INDEX(ENGINE!$T$5:$T$304,MATCH(7,EngDash,0)))} -> IND -1.5 | E11: {=IF($A11="","",IF(INDEX(ENGINE!$V$5:$V$304,MATCH(7,EngDash,0))="","",TEXT(INDEX(ENGINE!$W$5:$W$304,MATCH(7,EngDash,0)),"0.0")&" — "&INDEX(ENGINE!$X$5:$X$304,MATCH(7,EngDash,0))))} | F11: {=IF($A11="","",INDEX(ENGINE!$Z$5:$Z$304,MATCH(7,EngDash,0)))} | G11: {=IF($A11="","",INDEX(ENGINE!$AH$5:$AH$304,MATCH(7,EngDash,0)))} | H11: {=IF($A11="","",INDEX(ENGINE!$AG$5:$AG$304,MATCH(7,EngDash,0)))} -> 0 | I11: {=IF($A11="","",IF(INDEX(ENGINE!$AI$5:$AI$304,MATCH(7,EngDash,0))="","",INDEX(ENGINE!$AK$5:$AK$304,MATCH(7,EngDash,0))&" "&TEXT(INDEX(ENGINE!$AJ$5:$AJ$304,MATCH(7,EngDash,0)),"0.0")))} | J11: {=IF($A11="","",INDEX(ENGINE!$AM$5:$AM$304,MATCH(7,EngDash,0)))} | K11: {=IF($A11="","",INDEX(ENGINE!$AN$5:$AN$304,MATCH(7,EngDash,0)))} -> BET OVER at ≤ -3.0 | BET UNDER at ≥ 3.0 | L11: {=IF($A11="","",INDEX(ENGINE!$AQ$5:$AQ$304,MATCH(7,EngDash,0)))} -> PENDING BOTH | M11: {=IF($A11="","",INDEX(ENGINE!$AP$5:$AP$304,MATCH(7,EngDash,0)))} -> READY | N11: {=IF($A11="","",INDEX(ENGINE!$AS$5:$AS$304,MATCH(7,EngDash,0)))} -> 50 | O11: {=IF($A11="","",INDEX(ENGINE!$AT$5:$AT$304,MATCH(7,EngDash,0)))} -> 1 | P11: {=IF($A11="","",INDEX(RatMode,MATCH(INDEX(ENGINE!$E$5:$E$304,MATCH(7,EngDash,0)),RatTeams,0))&"/"&INDEX(RatMode,MATCH(INDEX(ENGINE!$F$5:$F$304,MATCH(7,EngDash,0)),RatTeams,0)))} -> BASIC/BASIC | Q11: {=IF($A11="","",INDEX(ENGINE!$AU$5:$AU$304,MATCH(7,EngDash,0)))}
A12: {=IF(IFERROR(MATCH(8,EngDash,0),"")="","",INDEX(ENGINE!$E$5:$E$304,MATCH(8,EngDash,0))&" @ "&INDEX(ENGINE!$F$5:$F$304,MATCH(8,EngDash,0))&IF(INDEX(ENGINE!$G$5:$G$304,MATCH(8,EngDash,0))="Y"," (N)",""))} -> CLE @ JAX | B12: {=IF($A12="","",INDEX(ENGINE!$D$5:$D$304,MATCH(8,EngDash,0)))} -> 46278 | C12: {=IF($A12="","",IF(INDEX(ENGINE!$U$5:$U$304,MATCH(8,EngDash,0))="","PENDING",INDEX(ENGINE!$F$5:$F$304,MATCH(8,EngDash,0))&" "&TEXT(INDEX(ENGINE!$U$5:$U$304,MATCH(8,EngDash,0)),"+0.0;-0.0;""PK""")))} -> PENDING | D12: {=IF($A12="","",INDEX(ENGINE!$T$5:$T$304,MATCH(8,EngDash,0)))} -> JAX -7.4 | E12: {=IF($A12="","",IF(INDEX(ENGINE!$V$5:$V$304,MATCH(8,EngDash,0))="","",TEXT(INDEX(ENGINE!$W$5:$W$304,MATCH(8,EngDash,0)),"0.0")&" — "&INDEX(ENGINE!$X$5:$X$304,MATCH(8,EngDash,0))))} | F12: {=IF($A12="","",INDEX(ENGINE!$Z$5:$Z$304,MATCH(8,EngDash,0)))} | G12: {=IF($A12="","",INDEX(ENGINE!$AH$5:$AH$304,MATCH(8,EngDash,0)))} | H12: {=IF($A12="","",INDEX(ENGINE!$AG$5:$AG$304,MATCH(8,EngDash,0)))} -> 0 | I12: {=IF($A12="","",IF(INDEX(ENGINE!$AI$5:$AI$304,MATCH(8,EngDash,0))="","",INDEX(ENGINE!$AK$5:$AK$304,MATCH(8,EngDash,0))&" "&TEXT(INDEX(ENGINE!$AJ$5:$AJ$304,MATCH(8,EngDash,0)),"0.0")))} | J12: {=IF($A12="","",INDEX(ENGINE!$AM$5:$AM$304,MATCH(8,EngDash,0)))} | K12: {=IF($A12="","",INDEX(ENGINE!$AN$5:$AN$304,MATCH(8,EngDash,0)))} -> BET OVER at ≤ -3.0 | BET UNDER at ≥ 3.0 | L12: {=IF($A12="","",INDEX(ENGINE!$AQ$5:$AQ$304,MATCH(8,EngDash,0)))} -> PENDING BOTH | M12: {=IF($A12="","",INDEX(ENGINE!$AP$5:$AP$304,MATCH(8,EngDash,0)))} -> READY | N12: {=IF($A12="","",INDEX(ENGINE!$AS$5:$AS$304,MATCH(8,EngDash,0)))} -> 30 | O12: {=IF($A12="","",INDEX(ENGINE!$AT$5:$AT$304,MATCH(8,EngDash,0)))} -> 13 | P12: {=IF($A12="","",INDEX(RatMode,MATCH(INDEX(ENGINE!$E$5:$E$304,MATCH(8,EngDash,0)),RatTeams,0))&"/"&INDEX(RatMode,MATCH(INDEX(ENGINE!$F$5:$F$304,MATCH(8,EngDash,0)),RatTeams,0)))} -> BASIC/BASIC | Q12: {=IF($A12="","",INDEX(ENGINE!$AU$5:$AU$304,MATCH(8,EngDash,0)))}
A13: {=IF(IFERROR(MATCH(9,EngDash,0),"")="","",INDEX(ENGINE!$E$5:$E$304,MATCH(9,EngDash,0))&" @ "&INDEX(ENGINE!$F$5:$F$304,MATCH(9,EngDash,0))&IF(INDEX(ENGINE!$G$5:$G$304,MATCH(9,EngDash,0))="Y"," (N)",""))} -> ATL @ PIT | B13: {=IF($A13="","",INDEX(ENGINE!$D$5:$D$304,MATCH(9,EngDash,0)))} -> 46278 | C13: {=IF($A13="","",IF(INDEX(ENGINE!$U$5:$U$304,MATCH(9,EngDash,0))="","PENDING",INDEX(ENGINE!$F$5:$F$304,MATCH(9,EngDash,0))&" "&TEXT(INDEX(ENGINE!$U$5:$U$304,MATCH(9,EngDash,0)),"+0.0;-0.0;""PK""")))} -> PENDING | D13: {=IF($A13="","",INDEX(ENGINE!$T$5:$T$304,MATCH(9,EngDash,0)))} -> PIT -2.3 | E13: {=IF($A13="","",IF(INDEX(ENGINE!$V$5:$V$304,MATCH(9,EngDash,0))="","",TEXT(INDEX(ENGINE!$W$5:$W$304,MATCH(9,EngDash,0)),"0.0")&" — "&INDEX(ENGINE!$X$5:$X$304,MATCH(9,EngDash,0))))} | F13: {=IF($A13="","",INDEX(ENGINE!$Z$5:$Z$304,MATCH(9,EngDash,0)))} | G13: {=IF($A13="","",INDEX(ENGINE!$AH$5:$AH$304,MATCH(9,EngDash,0)))} | H13: {=IF($A13="","",INDEX(ENGINE!$AG$5:$AG$304,MATCH(9,EngDash,0)))} -> 0 | I13: {=IF($A13="","",IF(INDEX(ENGINE!$AI$5:$AI$304,MATCH(9,EngDash,0))="","",INDEX(ENGINE!$AK$5:$AK$304,MATCH(9,EngDash,0))&" "&TEXT(INDEX(ENGINE!$AJ$5:$AJ$304,MATCH(9,EngDash,0)),"0.0")))} | J13: {=IF($A13="","",INDEX(ENGINE!$AM$5:$AM$304,MATCH(9,EngDash,0)))} | K13: {=IF($A13="","",INDEX(ENGINE!$AN$5:$AN$304,MATCH(9,EngDash,0)))} -> BET OVER at ≤ -3.0 | BET UNDER at ≥ 3.0 | L13: {=IF($A13="","",INDEX(ENGINE!$AQ$5:$AQ$304,MATCH(9,EngDash,0)))} -> PENDING BOTH | M13: {=IF($A13="","",INDEX(ENGINE!$AP$5:$AP$304,MATCH(9,EngDash,0)))} -> READY | N13: {=IF($A13="","",INDEX(ENGINE!$AS$5:$AS$304,MATCH(9,EngDash,0)))} -> 30 | O13: {=IF($A13="","",INDEX(ENGINE!$AT$5:$AT$304,MATCH(9,EngDash,0)))} -> 13 | P13: {=IF($A13="","",INDEX(RatMode,MATCH(INDEX(ENGINE!$E$5:$E$304,MATCH(9,EngDash,0)),RatTeams,0))&"/"&INDEX(RatMode,MATCH(INDEX(ENGINE!$F$5:$F$304,MATCH(9,EngDash,0)),RatTeams,0)))} -> BASIC/BASIC | Q13: {=IF($A13="","",INDEX(ENGINE!$AU$5:$AU$304,MATCH(9,EngDash,0)))}
A14: {=IF(IFERROR(MATCH(10,EngDash,0),"")="","",INDEX(ENGINE!$E$5:$E$304,MATCH(10,EngDash,0))&" @ "&INDEX(ENGINE!$F$5:$F$304,MATCH(10,EngDash,0))&IF(INDEX(ENGINE!$G$5:$G$304,MATCH(10,EngDash,0))="Y"," (N)",""))} -> NYJ @ TEN | B14: {=IF($A14="","",INDEX(ENGINE!$D$5:$D$304,MATCH(10,EngDash,0)))} -> 46278 | C14: {=IF($A14="","",IF(INDEX(ENGINE!$U$5:$U$304,MATCH(10,EngDash,0))="","PENDING",INDEX(ENGINE!$F$5:$F$304,MATCH(10,EngDash,0))&" "&TEXT(INDEX(ENGINE!$U$5:$U$304,MATCH(10,EngDash,0)),"+0.0;-0.0;""PK""")))} -> PENDING | D14: {=IF($A14="","",INDEX(ENGINE!$T$5:$T$304,MATCH(10,EngDash,0)))} -> TEN -3.1 | E14: {=IF($A14="","",IF(INDEX(ENGINE!$V$5:$V$304,MATCH(10,EngDash,0))="","",TEXT(INDEX(ENGINE!$W$5:$W$304,MATCH(10,EngDash,0)),"0.0")&" — "&INDEX(ENGINE!$X$5:$X$304,MATCH(10,EngDash,0))))} | F14: {=IF($A14="","",INDEX(ENGINE!$Z$5:$Z$304,MATCH(10,EngDash,0)))} | G14: {=IF($A14="","",INDEX(ENGINE!$AH$5:$AH$304,MATCH(10,EngDash,0)))} | H14: {=IF($A14="","",INDEX(ENGINE!$AG$5:$AG$304,MATCH(10,EngDash,0)))} -> 0 | I14: {=IF($A14="","",IF(INDEX(ENGINE!$AI$5:$AI$304,MATCH(10,EngDash,0))="","",INDEX(ENGINE!$AK$5:$AK$304,MATCH(10,EngDash,0))&" "&TEXT(INDEX(ENGINE!$AJ$5:$AJ$304,MATCH(10,EngDash,0)),"0.0")))} | J14: {=IF($A14="","",INDEX(ENGINE!$AM$5:$AM$304,MATCH(10,EngDash,0)))} | K14: {=IF($A14="","",INDEX(ENGINE!$AN$5:$AN$304,MATCH(10,EngDash,0)))} -> BET OVER at ≤ -3.0 | BET UNDER at ≥ 3.0 | L14: {=IF($A14="","",INDEX(ENGINE!$AQ$5:$AQ$304,MATCH(10,EngDash,0)))} -> PENDING BOTH | M14: {=IF($A14="","",INDEX(ENGINE!$AP$5:$AP$304,MATCH(10,EngDash,0)))} -> READY | N14: {=IF($A14="","",INDEX(ENGINE!$AS$5:$AS$304,MATCH(10,EngDash,0)))} -> 50 | O14: {=IF($A14="","",INDEX(ENGINE!$AT$5:$AT$304,MATCH(10,EngDash,0)))} -> 1 | P14: {=IF($A14="","",INDEX(RatMode,MATCH(INDEX(ENGINE!$E$5:$E$304,MATCH(10,EngDash,0)),RatTeams,0))&"/"&INDEX(RatMode,MATCH(INDEX(ENGINE!$F$5:$F$304,MATCH(10,EngDash,0)),RatTeams,0)))} -> BASIC/BASIC | Q14: {=IF($A14="","",INDEX(ENGINE!$AU$5:$AU$304,MATCH(10,EngDash,0)))}
A15: {=IF(IFERROR(MATCH(11,EngDash,0),"")="","",INDEX(ENGINE!$E$5:$E$304,MATCH(11,EngDash,0))&" @ "&INDEX(ENGINE!$F$5:$F$304,MATCH(11,EngDash,0))&IF(INDEX(ENGINE!$G$5:$G$304,MATCH(11,EngDash,0))="Y"," (N)",""))} -> ARI @ LAC | B15: {=IF($A15="","",INDEX(ENGINE!$D$5:$D$304,MATCH(11,EngDash,0)))} -> 46278 | C15: {=IF($A15="","",IF(INDEX(ENGINE!$U$5:$U$304,MATCH(11,EngDash,0))="","PENDING",INDEX(ENGINE!$F$5:$F$304,MATCH(11,EngDash,0))&" "&TEXT(INDEX(ENGINE!$U$5:$U$304,MATCH(11,EngDash,0)),"+0.0;-0.0;""PK""")))} -> PENDING | D15: {=IF($A15="","",INDEX(ENGINE!$T$5:$T$304,MATCH(11,EngDash,0)))} -> LAC -4.2 | E15: {=IF($A15="","",IF(INDEX(ENGINE!$V$5:$V$304,MATCH(11,EngDash,0))="","",TEXT(INDEX(ENGINE!$W$5:$W$304,MATCH(11,EngDash,0)),"0.0")&" — "&INDEX(ENGINE!$X$5:$X$304,MATCH(11,EngDash,0))))} | F15: {=IF($A15="","",INDEX(ENGINE!$Z$5:$Z$304,MATCH(11,EngDash,0)))} | G15: {=IF($A15="","",INDEX(ENGINE!$AH$5:$AH$304,MATCH(11,EngDash,0)))} | H15: {=IF($A15="","",INDEX(ENGINE!$AG$5:$AG$304,MATCH(11,EngDash,0)))} -> 0 | I15: {=IF($A15="","",IF(INDEX(ENGINE!$AI$5:$AI$304,MATCH(11,EngDash,0))="","",INDEX(ENGINE!$AK$5:$AK$304,MATCH(11,EngDash,0))&" "&TEXT(INDEX(ENGINE!$AJ$5:$AJ$304,MATCH(11,EngDash,0)),"0.0")))} | J15: {=IF($A15="","",INDEX(ENGINE!$AM$5:$AM$304,MATCH(11,EngDash,0)))} | K15: {=IF($A15="","",INDEX(ENGINE!$AN$5:$AN$304,MATCH(11,EngDash,0)))} -> BET OVER at ≤ -3.0 | BET UNDER at ≥ 3.0 | L15: {=IF($A15="","",INDEX(ENGINE!$AQ$5:$AQ$304,MATCH(11,EngDash,0)))} -> PENDING BOTH | M15: {=IF($A15="","",INDEX(ENGINE!$AP$5:$AP$304,MATCH(11,EngDash,0)))} -> READY | N15: {=IF($A15="","",INDEX(ENGINE!$AS$5:$AS$304,MATCH(11,EngDash,0)))} -> 30 | O15: {=IF($A15="","",INDEX(ENGINE!$AT$5:$AT$304,MATCH(11,EngDash,0)))} -> 13 | P15: {=IF($A15="","",INDEX(RatMode,MATCH(INDEX(ENGINE!$E$5:$E$304,MATCH(11,EngDash,0)),RatTeams,0))&"/"&INDEX(RatMode,MATCH(INDEX(ENGINE!$F$5:$F$304,MATCH(11,EngDash,0)),RatTeams,0)))} -> BASIC/BASIC | Q15: {=IF($A15="","",INDEX(ENGINE!$AU$5:$AU$304,MATCH(11,EngDash,0)))}
A16: {=IF(IFERROR(MATCH(12,EngDash,0),"")="","",INDEX(ENGINE!$E$5:$E$304,MATCH(12,EngDash,0))&" @ "&INDEX(ENGINE!$F$5:$F$304,MATCH(12,EngDash,0))&IF(INDEX(ENGINE!$G$5:$G$304,MATCH(12,EngDash,0))="Y"," (N)",""))} -> MIA @ LV | B16: {=IF($A16="","",INDEX(ENGINE!$D$5:$D$304,MATCH(12,EngDash,0)))} -> 46278 | C16: {=IF($A16="","",IF(INDEX(ENGINE!$U$5:$U$304,MATCH(12,EngDash,0))="","PENDING",INDEX(ENGINE!$F$5:$F$304,MATCH(12,EngDash,0))&" "&TEXT(INDEX(ENGINE!$U$5:$U$304,MATCH(12,EngDash,0)),"+0.0;-0.0;""PK""")))} -> PENDING | D16: {=IF($A16="","",INDEX(ENGINE!$T$5:$T$304,MATCH(12,EngDash,0)))} -> LV -0.7 | E16: {=IF($A16="","",IF(INDEX(ENGINE!$V$5:$V$304,MATCH(12,EngDash,0))="","",TEXT(INDEX(ENGINE!$W$5:$W$304,MATCH(12,EngDash,0)),"0.0")&" — "&INDEX(ENGINE!$X$5:$X$304,MATCH(12,EngDash,0))))} | F16: {=IF($A16="","",INDEX(ENGINE!$Z$5:$Z$304,MATCH(12,EngDash,0)))} | G16: {=IF($A16="","",INDEX(ENGINE!$AH$5:$AH$304,MATCH(12,EngDash,0)))} | H16: {=IF($A16="","",INDEX(ENGINE!$AG$5:$AG$304,MATCH(12,EngDash,0)))} -> 0 | I16: {=IF($A16="","",IF(INDEX(ENGINE!$AI$5:$AI$304,MATCH(12,EngDash,0))="","",INDEX(ENGINE!$AK$5:$AK$304,MATCH(12,EngDash,0))&" "&TEXT(INDEX(ENGINE!$AJ$5:$AJ$304,MATCH(12,EngDash,0)),"0.0")))} | J16: {=IF($A16="","",INDEX(ENGINE!$AM$5:$AM$304,MATCH(12,EngDash,0)))} | K16: {=IF($A16="","",INDEX(ENGINE!$AN$5:$AN$304,MATCH(12,EngDash,0)))} -> BET OVER at ≤ -3.0 | BET UNDER at ≥ 3.0 | L16: {=IF($A16="","",INDEX(ENGINE!$AQ$5:$AQ$304,MATCH(12,EngDash,0)))} -> PENDING BOTH | M16: {=IF($A16="","",INDEX(ENGINE!$AP$5:$AP$304,MATCH(12,EngDash,0)))} -> READY | N16: {=IF($A16="","",INDEX(ENGINE!$AS$5:$AS$304,MATCH(12,EngDash,0)))} -> 50 | O16: {=IF($A16="","",INDEX(ENGINE!$AT$5:$AT$304,MATCH(12,EngDash,0)))} -> 1 | P16: {=IF($A16="","",INDEX(RatMode,MATCH(INDEX(ENGINE!$E$5:$E$304,MATCH(12,EngDash,0)),RatTeams,0))&"/"&INDEX(RatMode,MATCH(INDEX(ENGINE!$F$5:$F$304,MATCH(12,EngDash,0)),RatTeams,0)))} -> BASIC/BASIC | Q16: {=IF($A16="","",INDEX(ENGINE!$AU$5:$AU$304,MATCH(12,EngDash,0)))}
A17: {=IF(IFERROR(MATCH(13,EngDash,0),"")="","",INDEX(ENGINE!$E$5:$E$304,MATCH(13,EngDash,0))&" @ "&INDEX(ENGINE!$F$5:$F$304,MATCH(13,EngDash,0))&IF(INDEX(ENGINE!$G$5:$G$304,MATCH(13,EngDash,0))="Y"," (N)",""))} -> GB @ MIN | B17: {=IF($A17="","",INDEX(ENGINE!$D$5:$D$304,MATCH(13,EngDash,0)))} -> 46278 | C17: {=IF($A17="","",IF(INDEX(ENGINE!$U$5:$U$304,MATCH(13,EngDash,0))="","PENDING",INDEX(ENGINE!$F$5:$F$304,MATCH(13,EngDash,0))&" "&TEXT(INDEX(ENGINE!$U$5:$U$304,MATCH(13,EngDash,0)),"+0.0;-0.0;""PK""")))} -> PENDING | D17: {=IF($A17="","",INDEX(ENGINE!$T$5:$T$304,MATCH(13,EngDash,0)))} -> MIN -1.6 | E17: {=IF($A17="","",IF(INDEX(ENGINE!$V$5:$V$304,MATCH(13,EngDash,0))="","",TEXT(INDEX(ENGINE!$W$5:$W$304,MATCH(13,EngDash,0)),"0.0")&" — "&INDEX(ENGINE!$X$5:$X$304,MATCH(13,EngDash,0))))} | F17: {=IF($A17="","",INDEX(ENGINE!$Z$5:$Z$304,MATCH(13,EngDash,0)))} | G17: {=IF($A17="","",INDEX(ENGINE!$AH$5:$AH$304,MATCH(13,EngDash,0)))} | H17: {=IF($A17="","",INDEX(ENGINE!$AG$5:$AG$304,MATCH(13,EngDash,0)))} -> 0 | I17: {=IF($A17="","",IF(INDEX(ENGINE!$AI$5:$AI$304,MATCH(13,EngDash,0))="","",INDEX(ENGINE!$AK$5:$AK$304,MATCH(13,EngDash,0))&" "&TEXT(INDEX(ENGINE!$AJ$5:$AJ$304,MATCH(13,EngDash,0)),"0.0")))} | J17: {=IF($A17="","",INDEX(ENGINE!$AM$5:$AM$304,MATCH(13,EngDash,0)))} | K17: {=IF($A17="","",INDEX(ENGINE!$AN$5:$AN$304,MATCH(13,EngDash,0)))} -> BET OVER at ≤ -3.0 | BET UNDER at ≥ 3.0 | L17: {=IF($A17="","",INDEX(ENGINE!$AQ$5:$AQ$304,MATCH(13,EngDash,0)))} -> PENDING BOTH | M17: {=IF($A17="","",INDEX(ENGINE!$AP$5:$AP$304,MATCH(13,EngDash,0)))} -> READY | N17: {=IF($A17="","",INDEX(ENGINE!$AS$5:$AS$304,MATCH(13,EngDash,0)))} -> 30 | O17: {=IF($A17="","",INDEX(ENGINE!$AT$5:$AT$304,MATCH(13,EngDash,0)))} -> 13 | P17: {=IF($A17="","",INDEX(RatMode,MATCH(INDEX(ENGINE!$E$5:$E$304,MATCH(13,EngDash,0)),RatTeams,0))&"/"&INDEX(RatMode,MATCH(INDEX(ENGINE!$F$5:$F$304,MATCH(13,EngDash,0)),RatTeams,0)))} -> BASIC/BASIC | Q17: {=IF($A17="","",INDEX(ENGINE!$AU$5:$AU$304,MATCH(13,EngDash,0)))}
A18: {=IF(IFERROR(MATCH(14,EngDash,0),"")="","",INDEX(ENGINE!$E$5:$E$304,MATCH(14,EngDash,0))&" @ "&INDEX(ENGINE!$F$5:$F$304,MATCH(14,EngDash,0))&IF(INDEX(ENGINE!$G$5:$G$304,MATCH(14,EngDash,0))="Y"," (N)",""))} -> WAS @ PHI | B18: {=IF($A18="","",INDEX(ENGINE!$D$5:$D$304,MATCH(14,EngDash,0)))} -> 46278 | C18: {=IF($A18="","",IF(INDEX(ENGINE!$U$5:$U$304,MATCH(14,EngDash,0))="","PENDING",INDEX(ENGINE!$F$5:$F$304,MATCH(14,EngDash,0))&" "&TEXT(INDEX(ENGINE!$U$5:$U$304,MATCH(14,EngDash,0)),"+0.0;-0.0;""PK""")))} -> PENDING | D18: {=IF($A18="","",INDEX(ENGINE!$T$5:$T$304,MATCH(14,EngDash,0)))} -> PHI -5.1 | E18: {=IF($A18="","",IF(INDEX(ENGINE!$V$5:$V$304,MATCH(14,EngDash,0))="","",TEXT(INDEX(ENGINE!$W$5:$W$304,MATCH(14,EngDash,0)),"0.0")&" — "&INDEX(ENGINE!$X$5:$X$304,MATCH(14,EngDash,0))))} | F18: {=IF($A18="","",INDEX(ENGINE!$Z$5:$Z$304,MATCH(14,EngDash,0)))} | G18: {=IF($A18="","",INDEX(ENGINE!$AH$5:$AH$304,MATCH(14,EngDash,0)))} | H18: {=IF($A18="","",INDEX(ENGINE!$AG$5:$AG$304,MATCH(14,EngDash,0)))} -> 0 | I18: {=IF($A18="","",IF(INDEX(ENGINE!$AI$5:$AI$304,MATCH(14,EngDash,0))="","",INDEX(ENGINE!$AK$5:$AK$304,MATCH(14,EngDash,0))&" "&TEXT(INDEX(ENGINE!$AJ$5:$AJ$304,MATCH(14,EngDash,0)),"0.0")))} | J18: {=IF($A18="","",INDEX(ENGINE!$AM$5:$AM$304,MATCH(14,EngDash,0)))} | K18: {=IF($A18="","",INDEX(ENGINE!$AN$5:$AN$304,MATCH(14,EngDash,0)))} -> BET OVER at ≤ -3.0 | BET UNDER at ≥ 3.0 | L18: {=IF($A18="","",INDEX(ENGINE!$AQ$5:$AQ$304,MATCH(14,EngDash,0)))} -> PENDING BOTH | M18: {=IF($A18="","",INDEX(ENGINE!$AP$5:$AP$304,MATCH(14,EngDash,0)))} -> READY | N18: {=IF($A18="","",INDEX(ENGINE!$AS$5:$AS$304,MATCH(14,EngDash,0)))} -> 50 | O18: {=IF($A18="","",INDEX(ENGINE!$AT$5:$AT$304,MATCH(14,EngDash,0)))} -> 1 | P18: {=IF($A18="","",INDEX(RatMode,MATCH(INDEX(ENGINE!$E$5:$E$304,MATCH(14,EngDash,0)),RatTeams,0))&"/"&INDEX(RatMode,MATCH(INDEX(ENGINE!$F$5:$F$304,MATCH(14,EngDash,0)),RatTeams,0)))} -> BASIC/BASIC | Q18: {=IF($A18="","",INDEX(ENGINE!$AU$5:$AU$304,MATCH(14,EngDash,0)))}
A19: {=IF(IFERROR(MATCH(15,EngDash,0),"")="","",INDEX(ENGINE!$E$5:$E$304,MATCH(15,EngDash,0))&" @ "&INDEX(ENGINE!$F$5:$F$304,MATCH(15,EngDash,0))&IF(INDEX(ENGINE!$G$5:$G$304,MATCH(15,EngDash,0))="Y"," (N)",""))} -> DAL @ NYG | B19: {=IF($A19="","",INDEX(ENGINE!$D$5:$D$304,MATCH(15,EngDash,0)))} -> 46278 | C19: {=IF($A19="","",IF(INDEX(ENGINE!$U$5:$U$304,MATCH(15,EngDash,0))="","PENDING",INDEX(ENGINE!$F$5:$F$304,MATCH(15,EngDash,0))&" "&TEXT(INDEX(ENGINE!$U$5:$U$304,MATCH(15,EngDash,0)),"+0.0;-0.0;""PK""")))} -> PENDING | D19: {=IF($A19="","",INDEX(ENGINE!$T$5:$T$304,MATCH(15,EngDash,0)))} -> NYG -2.3 | E19: {=IF($A19="","",IF(INDEX(ENGINE!$V$5:$V$304,MATCH(15,EngDash,0))="","",TEXT(INDEX(ENGINE!$W$5:$W$304,MATCH(15,EngDash,0)),"0.0")&" — "&INDEX(ENGINE!$X$5:$X$304,MATCH(15,EngDash,0))))} | F19: {=IF($A19="","",INDEX(ENGINE!$Z$5:$Z$304,MATCH(15,EngDash,0)))} | G19: {=IF($A19="","",INDEX(ENGINE!$AH$5:$AH$304,MATCH(15,EngDash,0)))} | H19: {=IF($A19="","",INDEX(ENGINE!$AG$5:$AG$304,MATCH(15,EngDash,0)))} -> 0 | I19: {=IF($A19="","",IF(INDEX(ENGINE!$AI$5:$AI$304,MATCH(15,EngDash,0))="","",INDEX(ENGINE!$AK$5:$AK$304,MATCH(15,EngDash,0))&" "&TEXT(INDEX(ENGINE!$AJ$5:$AJ$304,MATCH(15,EngDash,0)),"0.0")))} | J19: {=IF($A19="","",INDEX(ENGINE!$AM$5:$AM$304,MATCH(15,EngDash,0)))} | K19: {=IF($A19="","",INDEX(ENGINE!$AN$5:$AN$304,MATCH(15,EngDash,0)))} -> BET OVER at ≤ -3.0 | BET UNDER at ≥ 3.0 | L19: {=IF($A19="","",INDEX(ENGINE!$AQ$5:$AQ$304,MATCH(15,EngDash,0)))} -> PENDING BOTH | M19: {=IF($A19="","",INDEX(ENGINE!$AP$5:$AP$304,MATCH(15,EngDash,0)))} -> READY | N19: {=IF($A19="","",INDEX(ENGINE!$AS$5:$AS$304,MATCH(15,EngDash,0)))} -> 50 | O19: {=IF($A19="","",INDEX(ENGINE!$AT$5:$AT$304,MATCH(15,EngDash,0)))} -> 1 | P19: {=IF($A19="","",INDEX(RatMode,MATCH(INDEX(ENGINE!$E$5:$E$304,MATCH(15,EngDash,0)),RatTeams,0))&"/"&INDEX(RatMode,MATCH(INDEX(ENGINE!$F$5:$F$304,MATCH(15,EngDash,0)),RatTeams,0)))} -> BASIC/BASIC | Q19: {=IF($A19="","",INDEX(ENGINE!$AU$5:$AU$304,MATCH(15,EngDash,0)))}
A20: {=IF(IFERROR(MATCH(16,EngDash,0),"")="","",INDEX(ENGINE!$E$5:$E$304,MATCH(16,EngDash,0))&" @ "&INDEX(ENGINE!$F$5:$F$304,MATCH(16,EngDash,0))&IF(INDEX(ENGINE!$G$5:$G$304,MATCH(16,EngDash,0))="Y"," (N)",""))} -> DEN @ KC | B20: {=IF($A20="","",INDEX(ENGINE!$D$5:$D$304,MATCH(16,EngDash,0)))} -> 46279 | C20: {=IF($A20="","",IF(INDEX(ENGINE!$U$5:$U$304,MATCH(16,EngDash,0))="","PENDING",INDEX(ENGINE!$F$5:$F$304,MATCH(16,EngDash,0))&" "&TEXT(INDEX(ENGINE!$U$5:$U$304,MATCH(16,EngDash,0)),"+0.0;-0.0;""PK""")))} -> PENDING | D20: {=IF($A20="","",INDEX(ENGINE!$T$5:$T$304,MATCH(16,EngDash,0)))} -> DEN -0.4 | E20: {=IF($A20="","",IF(INDEX(ENGINE!$V$5:$V$304,MATCH(16,EngDash,0))="","",TEXT(INDEX(ENGINE!$W$5:$W$304,MATCH(16,EngDash,0)),"0.0")&" — "&INDEX(ENGINE!$X$5:$X$304,MATCH(16,EngDash,0))))} | F20: {=IF($A20="","",INDEX(ENGINE!$Z$5:$Z$304,MATCH(16,EngDash,0)))} | G20: {=IF($A20="","",INDEX(ENGINE!$AH$5:$AH$304,MATCH(16,EngDash,0)))} | H20: {=IF($A20="","",INDEX(ENGINE!$AG$5:$AG$304,MATCH(16,EngDash,0)))} -> 0 | I20: {=IF($A20="","",IF(INDEX(ENGINE!$AI$5:$AI$304,MATCH(16,EngDash,0))="","",INDEX(ENGINE!$AK$5:$AK$304,MATCH(16,EngDash,0))&" "&TEXT(INDEX(ENGINE!$AJ$5:$AJ$304,MATCH(16,EngDash,0)),"0.0")))} | J20: {=IF($A20="","",INDEX(ENGINE!$AM$5:$AM$304,MATCH(16,EngDash,0)))} | K20: {=IF($A20="","",INDEX(ENGINE!$AN$5:$AN$304,MATCH(16,EngDash,0)))} -> BET OVER at ≤ -3.0 | BET UNDER at ≥ 3.0 | L20: {=IF($A20="","",INDEX(ENGINE!$AQ$5:$AQ$304,MATCH(16,EngDash,0)))} -> PENDING BOTH | M20: {=IF($A20="","",INDEX(ENGINE!$AP$5:$AP$304,MATCH(16,EngDash,0)))} -> READY | N20: {=IF($A20="","",INDEX(ENGINE!$AS$5:$AS$304,MATCH(16,EngDash,0)))} -> 50 | O20: {=IF($A20="","",INDEX(ENGINE!$AT$5:$AT$304,MATCH(16,EngDash,0)))} -> 1 | P20: {=IF($A20="","",INDEX(RatMode,MATCH(INDEX(ENGINE!$E$5:$E$304,MATCH(16,EngDash,0)),RatTeams,0))&"/"&INDEX(RatMode,MATCH(INDEX(ENGINE!$F$5:$F$304,MATCH(16,EngDash,0)),RatTeams,0)))} -> BASIC/BASIC | Q20: {=IF($A20="","",INDEX(ENGINE!$AU$5:$AU$304,MATCH(16,EngDash,0)))}

Sheet ENGINE
A1: MATCHUP ENGINE — full bridge from neutral-field rating difference to final number, one row per game
A2: Sign convention: FinalMargin = projected HOME margin (+ = home wins). Spreads display book-style (negative = favorite). SpreadEdge = FinalMargin + MarketHomeSpread: positive = value on HOME, negative = value on AWAY. Every step between ratings and final number is a visible column.
A4: Seq | B4: GameID | C4: Wk | D4: Date | E4: Away | F4: Home | G4: Neutral | H4: Roof | I4: DashOrd | J4: AwayEff | K4: HomeEff | L4: NeutralDiff | M4: HFA | N4: QBadj | O4: RestAdj | P4: ManualAdj | Q4: BaseMargin | R4: OverrideMargin | S4: FinalMargin | T4: ModelSpread | U4: MktHomeSpr | V4: SpreadEdge | W4: AbsEdge | X4: SupportedSide | Y4: ATSconf | Z4: ATS_REC | AA4: AwayExpPts | AB4: HomeExpPts | AC4: QBTotAdj | AD4: ManualTotAdj | AE4: BaseTotal | AF4: OverrideTotal | AG4: FinalTotal | AH4: MktTotal | AI4: TotalEdge | AJ4: AbsTotEdge | AK4: Direction | AL4: Totconf | AM4: TOTAL_REC | AN4: TotalTrigger | AO4: QBUnc | AP4: DQ | AQ4: OpsStatus | AR4: OverrideFlag | AS4: ReviewPriority | AT4: RPrank | AU4: Notes
A5: 1 | B5: {=IFERROR(INDEX(SchedZone,MATCH($A5,SchedSeq,0),MAP!$B$6),"")} -> 2026_01_NE_SEA | C5: {=IF($B5="","",INDEX(SchedZone,MATCH($A5,SchedSeq,0),MAP!$B$4))} -> 1 | D5: {=IF($B5="","",INDEX(SchedZone,MATCH($A5,SchedSeq,0),MAP!$B$7))} -> 46274 | E5: {=IF($B5="","",IF(COUNTIF(Teams,INDEX(SchedZone,MATCH($A5,SchedSeq,0),MAP!$B$10))>0,INDEX(SchedZone,MATCH($A5,SchedSeq,0),MAP!$B$10),IFERROR(INDEX(LISTS!$D$2:$D$12,MATCH(INDEX(SchedZone,MATCH($A5,SchedSeq,0),MAP!$B$10),LISTS!$C$2:$C$12,0)),"⚠ "&INDEX(SchedZone,MATCH($A5,SchedSeq,0),MAP!$B$10))))} -> NE | F5: {=IF($B5="","",IF(COUNTIF(Teams,INDEX(SchedZone,MATCH($A5,SchedSeq,0),MAP!$B$12))>0,INDEX(SchedZone,MATCH($A5,SchedSeq,0),MAP!$B$12),IFERROR(INDEX(LISTS!$D$2:$D$12,MATCH(INDEX(SchedZone,MATCH($A5,SchedSeq,0),MAP!$B$12),LISTS!$C$2:$C$12,0)),"⚠ "&INDEX(SchedZone,MATCH($A5,SchedSeq,0),MAP!$B$12))))} -> SEA | G5: {=IF($B5="","",IF(INDEX(SchedZone,MATCH($A5,SchedSeq,0),MAP!$B$14)="Neutral","Y",""))} | H5: {=IF($B5="","",INDEX(SchedZone,MATCH($A5,SchedSeq,0),MAP!$B$17))} -> outdoors | I5: =IF(OR($B5="",$C5<>CurrentWeek),"",COUNTIF($C$5:$C5,CurrentWeek)) -> 1 | J5: {=IF($B5="","",IFERROR(INDEX(RatEff,MATCH($E5,RatTeams,0)),"⚠ TEAM NOT FOUND"))} -> 2.09 | K5: {=IF($B5="","",IFERROR(INDEX(RatEff,MATCH($F5,RatTeams,0)),"⚠ TEAM NOT FOUND"))} -> 4.1 | L5: =IF(OR($B5="",NOT(ISNUMBER($J5)),NOT(ISNUMBER($K5))),"",$K5-$J5) -> 2.01 | M5: {=IF($B5="","",IF($G5="Y",NeutralHFA,IFERROR(INDEX(HFAexcVal,MATCH($F5,HFAexcTeam,0)),HFA_Base)))} -> 1.6 | N5: {=IF($B5="","",IFERROR(INDEX(QBSpreadEff,MATCH($F5,QBTeams,0)),0)-IFERROR(INDEX(QBSpreadEff,MATCH($E5,QBTeams,0)),0))} -> 0 | O5: {=IF($B5="","",IFERROR(MEDIAN(-RestCapPts,RestCapPts,RestPerDay*(INDEX(SchedZone,MATCH($A5,SchedSeq,0),MAP!$B$16)-INDEX(SchedZone,MATCH($A5,SchedSeq,0),MAP!$B$15))),0))} -> 0 | P5: =IF($B5="","",SUMIFS(AdjSpread,AdjGameID,$B5,AdjTeam,$F5,AdjActive,1)-SUMIFS(AdjSpread,AdjGameID,$B5,AdjTeam,$E5,AdjActive,1)) -> 0 | Q5: =IF($L5="","",ROUND($L5+$M5+$N5+$O5+$P5,2)) -> 3.61 | S5: =IF(AND($R5="",$Q5=""),"",IF($R5<>"",$R5,$Q5)) -> 3.61 | T5: =IF($S5="","",IF(ABS($S5)<0.05,"PK",IF($S5>0,$F5&" "&TEXT(-$S5,"+0.0;-0.0"),$E5&" "&TEXT($S5,"+0.0;-0.0")))) -> SEA -3.6 | U5: {=IF($B5="","",IFERROR(INDEX(MktHomeSpread,MATCH($B5,MktGameID,0)),""))} | V5: =IF(OR($S5="",$U5=""),"",ROUND($S5+$U5,2)) | W5: =IF($V5="","",ABS($V5)) | X5: =IF($V5="","",IF($V5>0,$F5&" "&TEXT($U5,"+0.0;-0.0;""PK"""),$E5&" "&TEXT(-$U5,"+0.0;-0.0;""PK"""))) | Y5: {=IF($B5="","",IF((IF(AND(IFERROR(INDEX(RatGP,MATCH($E5,RatTeams,0)),0)>=MinGamesTrust,IFERROR(INDEX(RatGP,MATCH($F5,RatTeams,0)),0)>=MinGamesTrust),1,0)+IF($AP5="READY",1,0)+IF(AND(IFERROR(INDEX(RatMode,MATCH($E5,RatTeams,0)),"")="ENHANCED",IFERROR(INDEX(RatMode,MATCH($F5,RatTeams,0)),"")="ENHANCED"),1,0)+IF($AO5="",1,0)+IF(IFERROR(INDEX(MktStale,MATCH($B5,MktGameID,0)),"")<>"STALE",1,0))>=5,"High",IF((IF(AND(IFERROR(INDEX(RatGP,MATCH($E5,RatTeams,0)),0)>=MinGamesTrust,IFERROR(INDEX(RatGP,MATCH($F5,RatTeams,0)),0)>=MinGamesTrust),1,0)+IF($AP5="READY",1,0)+IF(AND(IFERROR(INDEX(RatMode,MATCH($E5,RatTeams,0)),"")="ENHANCED",IFERROR(INDEX(RatMode,MATCH($F5,RatTeams,0)),"")="ENHANCED"),1,0)+IF($AO5="",1,0)+IF(IFERROR(INDEX(MktStale,MATCH($B5,MktGameID,0)),"")<>"STALE",1,0))>=4,"Medium","Low")))} -> Low | Z5: =IF(OR($B5="",$V5=""),"",IF(LEFT($AP5,7)="BLOCKED","",IF(AND($W5>=BetATS,$Y5<>"Low"),IF(AND(EnableBetLabels="Y",$Y5="High",$AP5="READY",ABS(IF($P5="",0,$P5))<=AdjCap),"BET","STRONG INVESTIGATE"),IF($W5>=InvATS,"INVESTIGATE",IF(AND($W5>=LeanATS,$Y5<>"Low"),"LEAN",""))))) | AA5: {=IF($B5="","",IFERROR(ROUND(((1-TotRegress)*0.5*(INDEX(CalcOffPl,MATCH($E5,CalcTeams,0))+INDEX(CalcDefPl,MATCH($F5,CalcTeams,0)))+TotRegress*LeaguePlays)*(INDEX(CalcOffAdj,MATCH($E5,CalcTeams,0))+INDEX(CalcDefAdj,MATCH($F5,CalcTeams,0))-LeaguePPP)+DstPts,2),""))} -> 0 | AB5: {=IF($B5="","",IFERROR(ROUND(((1-TotRegress)*0.5*(INDEX(CalcOffPl,MATCH($F5,CalcTeams,0))+INDEX(CalcDefPl,MATCH($E5,CalcTeams,0)))+TotRegress*LeaguePlays)*(INDEX(CalcOffAdj,MATCH($F5,CalcTeams,0))+INDEX(CalcDefAdj,MATCH($E5,CalcTeams,0))-LeaguePPP)+DstPts,2),""))} -> 0 | AC5: {=IF($B5="","",IFERROR(INDEX(QBTotEff,MATCH($F5,QBTeams,0)),0)+IFERROR(INDEX(QBTotEff,MATCH($E5,QBTeams,0)),0))} -> 0 | AD5: =IF($B5="","",SUMIFS(AdjTot,AdjGameID,$B5,AdjActive,1)) -> 0 | AE5: =IF(OR($AA5="",$AB5=""),"",ROUND($AA5+$AB5+$AC5+$AD5,2)) -> 0 | AG5: =IF(AND($AF5="",$AE5=""),"",IF($AF5<>"",$AF5,$AE5)) -> 0 | AH5: {=IF($B5="","",IFERROR(INDEX(MktTotal,MATCH($B5,MktGameID,0)),""))} | AI5: =IF(OR($AG5="",$AH5=""),"",ROUND($AG5-$AH5,2)) | AJ5: =IF($AI5="","",ABS($AI5)) | AK5: =IF($AI5="","",IF($AI5>0.05,"OVER",IF($AI5<-0.05,"UNDER","—"))) | AL5: {=IF($B5="","",IF((IF(AND(IFERROR(INDEX(RatGP,MATCH($E5,RatTeams,0)),0)>=MinGamesTrust,IFERROR(INDEX(RatGP,MATCH($F5,RatTeams,0)),0)>=MinGamesTrust),1,0)+IF($AP5="READY",1,0)+IF($AO5="",1,0)+IF(IFERROR(INDEX(MktStale,MATCH($B5,MktGameID,0)),"")<>"STALE",1,0)+IF(ABS(IF($AD5="",0,$AD5))<=AdjCap,1,0))>=5,"High",IF((IF(AND(IFERROR(INDEX(RatGP,MATCH($E5,RatTeams,0)),0)>=MinGamesTrust,IFERROR(INDEX(RatGP,MATCH($F5,RatTeams,0)),0)>=MinGamesTrust),1,0)+IF($AP5="READY",1,0)+IF($AO5="",1,0)+IF(IFERROR(INDEX(MktStale,MATCH($B5,MktGameID,0)),"")<>"STALE",1,0)+IF(ABS(IF($AD5="",0,$AD5))<=AdjCap,1,0))>=4,"Medium","Low")))} -> Medium | AM5: =IF(OR($B5="",$AI5=""),"",IF(LEFT($AP5,7)="BLOCKED","",IF(AND($AJ5>=BetTot,$AL5<>"Low"),IF(AND(EnableBetLabels="Y",$AL5="High",$AP5="READY"),"BET ","STRONG INVESTIGATE ")&$AK5,IF($AJ5>=InvTot,"INVESTIGATE "&$AK5,IF(AND($AJ5>=LeanTot,$AL5<>"Low"),"LEAN "&$AK5,""))))) | AN5: =IF($AG5="","","BET OVER at ≤ "&TEXT($AG5-BetTot,"0.0")&" | BET UNDER at ≥ "&TEXT($AG5+BetTot,"0.0")) -> BET OVER at ≤ -3.0 | BET UNDER at ≥ 3.0 | AO5: {=IF($B5="","",IF(OR(IFERROR(INDEX(QBFlag,MATCH($F5,QBTeams,0)),1)=1,IFERROR(INDEX(QBFlag,MATCH($E5,QBTeams,0)),1)=1),"QB UNCERTAIN",""))} | AP5: {=IF($B5="","",IFERROR(INDEX(DQStatus,MATCH($B5,DQGameID,0)),"BLOCKED — DQ ROW NOT FOUND"))} -> READY | AQ5: {=IF($B5="","",IF(LEFT($AP5,7)="BLOCKED",IF($AP5="BLOCKED","BLOCKED — see DATA QUALITY",$AP5),IF(AND($U5="",$AH5=""),"PENDING BOTH",IF($U5="","PENDING SPREAD",IF($AH5="","PENDING TOTAL",IF(IFERROR(INDEX(MktStale,MATCH($B5,MktGameID,0)),"")="STALE","STALE LINE",IF($AO5<>"",$AO5,IF(OR(NOT(ISNUMBER($J5)),NOT(ISNUMBER($K5))),"DATA INCOMPLETE","READY"))))))))} -> PENDING BOTH | AR5: =IF(OR($R5<>"",$AF5<>""),"OVERRIDE","") | AS5: {=IF(OR($B5="",$C5<>CurrentWeek),"",ROUND(25*MIN(1,IF($W5="",0,$W5)/5)+20*IF($AP5="READY",1,0)+20*IF($AO5="",1,0)+15*IF(IFERROR(INDEX(MktStale,MATCH($B5,MktGameID,0)),"x")="OK",1,0)+10*MAX(0,1-ABS(IF($P5="",0,$P5))/AdjCap)+10*IF(AND($Z5<>"",$AM5<>""),1,0),0))} -> 50 | AT5: =IF($AS5="","",RANK($AS5,$AS$5:$AS$304,0)) -> 1
A6: 2 | B6: {=IFERROR(INDEX(SchedZone,MATCH($A6,SchedSeq,0),MAP!$B$6),"")} -> 2026_01_SF_LA | C6: {=IF($B6="","",INDEX(SchedZone,MATCH($A6,SchedSeq,0),MAP!$B$4))} -> 1 | D6: {=IF($B6="","",INDEX(SchedZone,MATCH($A6,SchedSeq,0),MAP!$B$7))} -> 46275 | E6: {=IF($B6="","",IF(COUNTIF(Teams,INDEX(SchedZone,MATCH($A6,SchedSeq,0),MAP!$B$10))>0,INDEX(SchedZone,MATCH($A6,SchedSeq,0),MAP!$B$10),IFERROR(INDEX(LISTS!$D$2:$D$12,MATCH(INDEX(SchedZone,MATCH($A6,SchedSeq,0),MAP!$B$10),LISTS!$C$2:$C$12,0)),"⚠ "&INDEX(SchedZone,MATCH($A6,SchedSeq,0),MAP!$B$10))))} -> SF | F6: {=IF($B6="","",IF(COUNTIF(Teams,INDEX(SchedZone,MATCH($A6,SchedSeq,0),MAP!$B$12))>0,INDEX(SchedZone,MATCH($A6,SchedSeq,0),MAP!$B$12),IFERROR(INDEX(LISTS!$D$2:$D$12,MATCH(INDEX(SchedZone,MATCH($A6,SchedSeq,0),MAP!$B$12),LISTS!$C$2:$C$12,0)),"⚠ "&INDEX(SchedZone,MATCH($A6,SchedSeq,0),MAP!$B$12))))} -> LA | G6: {=IF($B6="","",IF(INDEX(SchedZone,MATCH($A6,SchedSeq,0),MAP!$B$14)="Neutral","Y",""))} -> Y | H6: {=IF($B6="","",INDEX(SchedZone,MATCH($A6,SchedSeq,0),MAP!$B$17))} -> dome | I6: =IF(OR($B6="",$C6<>CurrentWeek),"",COUNTIF($C$5:$C6,CurrentWeek)) -> 2 | J6: {=IF($B6="","",IFERROR(INDEX(RatEff,MATCH($E6,RatTeams,0)),"⚠ TEAM NOT FOUND"))} -> 1.78 | K6: {=IF($B6="","",IFERROR(INDEX(RatEff,MATCH($F6,RatTeams,0)),"⚠ TEAM NOT FOUND"))} -> 4.09 | L6: =IF(OR($B6="",NOT(ISNUMBER($J6)),NOT(ISNUMBER($K6))),"",$K6-$J6) -> 2.31 | M6: {=IF($B6="","",IF($G6="Y",NeutralHFA,IFERROR(INDEX(HFAexcVal,MATCH($F6,HFAexcTeam,0)),HFA_Base)))} -> 0 | N6: {=IF($B6="","",IFERROR(INDEX(QBSpreadEff,MATCH($F6,QBTeams,0)),0)-IFERROR(INDEX(QBSpreadEff,MATCH($E6,QBTeams,0)),0))} -> 0 | O6: {=IF($B6="","",IFERROR(MEDIAN(-RestCapPts,RestCapPts,RestPerDay*(INDEX(SchedZone,MATCH($A6,SchedSeq,0),MAP!$B$16)-INDEX(SchedZone,MATCH($A6,SchedSeq,0),MAP!$B$15))),0))} -> 0 | P6: =IF($B6="","",SUMIFS(AdjSpread,AdjGameID,$B6,AdjTeam,$F6,AdjActive,1)-SUMIFS(AdjSpread,AdjGameID,$B6,AdjTeam,$E6,AdjActive,1)) -> 0 | Q6: =IF($L6="","",ROUND($L6+$M6+$N6+$O6+$P6,2)) -> 2.31 | S6: =IF(AND($R6="",$Q6=""),"",IF($R6<>"",$R6,$Q6)) -> 2.31 | T6: =IF($S6="","",IF(ABS($S6)<0.05,"PK",IF($S6>0,$F6&" "&TEXT(-$S6,"+0.0;-0.0"),$E6&" "&TEXT($S6,"+0.0;-0.0")))) -> LA -2.3 | U6: {=IF($B6="","",IFERROR(INDEX(MktHomeSpread,MATCH($B6,MktGameID,0)),""))} | V6: =IF(OR($S6="",$U6=""),"",ROUND($S6+$U6,2)) | W6: =IF($V6="","",ABS($V6)) | X6: =IF($V6="","",IF($V6>0,$F6&" "&TEXT($U6,"+0.0;-0.0;""PK"""),$E6&" "&TEXT(-$U6,"+0.0;-0.0;""PK"""))) | Y6: {=IF($B6="","",IF((IF(AND(IFERROR(INDEX(RatGP,MATCH($E6,RatTeams,0)),0)>=MinGamesTrust,IFERROR(INDEX(RatGP,MATCH($F6,RatTeams,0)),0)>=MinGamesTrust),1,0)+IF($AP6="READY",1,0)+IF(AND(IFERROR(INDEX(RatMode,MATCH($E6,RatTeams,0)),"")="ENHANCED",IFERROR(INDEX(RatMode,MATCH($F6,RatTeams,0)),"")="ENHANCED"),1,0)+IF($AO6="",1,0)+IF(IFERROR(INDEX(MktStale,MATCH($B6,MktGameID,0)),"")<>"STALE",1,0))>=5,"High",IF((IF(AND(IFERROR(INDEX(RatGP,MATCH($E6,RatTeams,0)),0)>=MinGamesTrust,IFERROR(INDEX(RatGP,MATCH($F6,RatTeams,0)),0)>=MinGamesTrust),1,0)+IF($AP6="READY",1,0)+IF(AND(IFERROR(INDEX(RatMode,MATCH($E6,RatTeams,0)),"")="ENHANCED",IFERROR(INDEX(RatMode,MATCH($F6,RatTeams,0)),"")="ENHANCED"),1,0)+IF($AO6="",1,0)+IF(IFERROR(INDEX(MktStale,MATCH($B6,MktGameID,0)),"")<>"STALE",1,0))>=4,"Medium","Low")))} -> Low | Z6: =IF(OR($B6="",$V6=""),"",IF(LEFT($AP6,7)="BLOCKED","",IF(AND($W6>=BetATS,$Y6<>"Low"),IF(AND(EnableBetLabels="Y",$Y6="High",$AP6="READY",ABS(IF($P6="",0,$P6))<=AdjCap),"BET","STRONG INVESTIGATE"),IF($W6>=InvATS,"INVESTIGATE",IF(AND($W6>=LeanATS,$Y6<>"Low"),"LEAN",""))))) | AA6: {=IF($B6="","",IFERROR(ROUND(((1-TotRegress)*0.5*(INDEX(CalcOffPl,MATCH($E6,CalcTeams,0))+INDEX(CalcDefPl,MATCH($F6,CalcTeams,0)))+TotRegress*LeaguePlays)*(INDEX(CalcOffAdj,MATCH($E6,CalcTeams,0))+INDEX(CalcDefAdj,MATCH($F6,CalcTeams,0))-LeaguePPP)+DstPts,2),""))} -> 0 | AB6: {=IF($B6="","",IFERROR(ROUND(((1-TotRegress)*0.5*(INDEX(CalcOffPl,MATCH($F6,CalcTeams,0))+INDEX(CalcDefPl,MATCH($E6,CalcTeams,0)))+TotRegress*LeaguePlays)*(INDEX(CalcOffAdj,MATCH($F6,CalcTeams,0))+INDEX(CalcDefAdj,MATCH($E6,CalcTeams,0))-LeaguePPP)+DstPts,2),""))} -> 0 | AC6: {=IF($B6="","",IFERROR(INDEX(QBTotEff,MATCH($F6,QBTeams,0)),0)+IFERROR(INDEX(QBTotEff,MATCH($E6,QBTeams,0)),0))} -> 0 | AD6: =IF($B6="","",SUMIFS(AdjTot,AdjGameID,$B6,AdjActive,1)) -> 0 | AE6: =IF(OR($AA6="",$AB6=""),"",ROUND($AA6+$AB6+$AC6+$AD6,2)) -> 0 | AG6: =IF(AND($AF6="",$AE6=""),"",IF($AF6<>"",$AF6,$AE6)) -> 0 | AH6: {=IF($B6="","",IFERROR(INDEX(MktTotal,MATCH($B6,MktGameID,0)),""))} | AI6: =IF(OR($AG6="",$AH6=""),"",ROUND($AG6-$AH6,2)) | AJ6: =IF($AI6="","",ABS($AI6)) | AK6: =IF($AI6="","",IF($AI6>0.05,"OVER",IF($AI6<-0.05,"UNDER","—"))) | AL6: {=IF($B6="","",IF((IF(AND(IFERROR(INDEX(RatGP,MATCH($E6,RatTeams,0)),0)>=MinGamesTrust,IFERROR(INDEX(RatGP,MATCH($F6,RatTeams,0)),0)>=MinGamesTrust),1,0)+IF($AP6="READY",1,0)+IF($AO6="",1,0)+IF(IFERROR(INDEX(MktStale,MATCH($B6,MktGameID,0)),"")<>"STALE",1,0)+IF(ABS(IF($AD6="",0,$AD6))<=AdjCap,1,0))>=5,"High",IF((IF(AND(IFERROR(INDEX(RatGP,MATCH($E6,RatTeams,0)),0)>=MinGamesTrust,IFERROR(INDEX(RatGP,MATCH($F6,RatTeams,0)),0)>=MinGamesTrust),1,0)+IF($AP6="READY",1,0)+IF($AO6="",1,0)+IF(IFERROR(INDEX(MktStale,MATCH($B6,MktGameID,0)),"")<>"STALE",1,0)+IF(ABS(IF($AD6="",0,$AD6))<=AdjCap,1,0))>=4,"Medium","Low")))} -> Medium | AM6: =IF(OR($B6="",$AI6=""),"",IF(LEFT($AP6,7)="BLOCKED","",IF(AND($AJ6>=BetTot,$AL6<>"Low"),IF(AND(EnableBetLabels="Y",$AL6="High",$AP6="READY"),"BET ","STRONG INVESTIGATE ")&$AK6,IF($AJ6>=InvTot,"INVESTIGATE "&$AK6,IF(AND($AJ6>=LeanTot,$AL6<>"Low"),"LEAN "&$AK6,""))))) | AN6: =IF($AG6="","","BET OVER at ≤ "&TEXT($AG6-BetTot,"0.0")&" | BET UNDER at ≥ "&TEXT($AG6+BetTot,"0.0")) -> BET OVER at ≤ -3.0 | BET UNDER at ≥ 3.0 | AO6: {=IF($B6="","",IF(OR(IFERROR(INDEX(QBFlag,MATCH($F6,QBTeams,0)),1)=1,IFERROR(INDEX(QBFlag,MATCH($E6,QBTeams,0)),1)=1),"QB UNCERTAIN",""))} | AP6: {=IF($B6="","",IFERROR(INDEX(DQStatus,MATCH($B6,DQGameID,0)),"BLOCKED — DQ ROW NOT FOUND"))} -> READY | AQ6: {=IF($B6="","",IF(LEFT($AP6,7)="BLOCKED",IF($AP6="BLOCKED","BLOCKED — see DATA QUALITY",$AP6),IF(AND($U6="",$AH6=""),"PENDING BOTH",IF($U6="","PENDING SPREAD",IF($AH6="","PENDING TOTAL",IF(IFERROR(INDEX(MktStale,MATCH($B6,MktGameID,0)),"")="STALE","STALE LINE",IF($AO6<>"",$AO6,IF(OR(NOT(ISNUMBER($J6)),NOT(ISNUMBER($K6))),"DATA INCOMPLETE","READY"))))))))} -> PENDING BOTH | AR6: =IF(OR($R6<>"",$AF6<>""),"OVERRIDE","") | AS6: {=IF(OR($B6="",$C6<>CurrentWeek),"",ROUND(25*MIN(1,IF($W6="",0,$W6)/5)+20*IF($AP6="READY",1,0)+20*IF($AO6="",1,0)+15*IF(IFERROR(INDEX(MktStale,MATCH($B6,MktGameID,0)),"x")="OK",1,0)+10*MAX(0,1-ABS(IF($P6="",0,$P6))/AdjCap)+10*IF(AND($Z6<>"",$AM6<>""),1,0),0))} -> 50 | AT6: =IF($AS6="","",RANK($AS6,$AS$5:$AS$304,0)) -> 1
A7: 3 | B7: {=IFERROR(INDEX(SchedZone,MATCH($A7,SchedSeq,0),MAP!$B$6),"")} -> 2026_01_CHI_CAR | C7: {=IF($B7="","",INDEX(SchedZone,MATCH($A7,SchedSeq,0),MAP!$B$4))} -> 1 | D7: {=IF($B7="","",INDEX(SchedZone,MATCH($A7,SchedSeq,0),MAP!$B$7))} -> 46278 | E7: {=IF($B7="","",IF(COUNTIF(Teams,INDEX(SchedZone,MATCH($A7,SchedSeq,0),MAP!$B$10))>0,INDEX(SchedZone,MATCH($A7,SchedSeq,0),MAP!$B$10),IFERROR(INDEX(LISTS!$D$2:$D$12,MATCH(INDEX(SchedZone,MATCH($A7,SchedSeq,0),MAP!$B$10),LISTS!$C$2:$C$12,0)),"⚠ "&INDEX(SchedZone,MATCH($A7,SchedSeq,0),MAP!$B$10))))} -> CHI | F7: {=IF($B7="","",IF(COUNTIF(Teams,INDEX(SchedZone,MATCH($A7,SchedSeq,0),MAP!$B$12))>0,INDEX(SchedZone,MATCH($A7,SchedSeq,0),MAP!$B$12),IFERROR(INDEX(LISTS!$D$2:$D$12,MATCH(INDEX(SchedZone,MATCH($A7,SchedSeq,0),MAP!$B$12),LISTS!$C$2:$C$12,0)),"⚠ "&INDEX(SchedZone,MATCH($A7,SchedSeq,0),MAP!$B$12))))} -> CAR | G7: {=IF($B7="","",IF(INDEX(SchedZone,MATCH($A7,SchedSeq,0),MAP!$B$14)="Neutral","Y",""))} | H7: {=IF($B7="","",INDEX(SchedZone,MATCH($A7,SchedSeq,0),MAP!$B$17))} -> outdoors | I7: =IF(OR($B7="",$C7<>CurrentWeek),"",COUNTIF($C$5:$C7,CurrentWeek)) -> 3 | J7: {=IF($B7="","",IFERROR(INDEX(RatEff,MATCH($E7,RatTeams,0)),"⚠ TEAM NOT FOUND"))} -> 0.86 | K7: {=IF($B7="","",IFERROR(INDEX(RatEff,MATCH($F7,RatTeams,0)),"⚠ TEAM NOT FOUND"))} -> -1.3 | L7: =IF(OR($B7="",NOT(ISNUMBER($J7)),NOT(ISNUMBER($K7))),"",$K7-$J7) -> -2.16 | M7: {=IF($B7="","",IF($G7="Y",NeutralHFA,IFERROR(INDEX(HFAexcVal,MATCH($F7,HFAexcTeam,0)),HFA_Base)))} -> 1.6 | N7: {=IF($B7="","",IFERROR(INDEX(QBSpreadEff,MATCH($F7,QBTeams,0)),0)-IFERROR(INDEX(QBSpreadEff,MATCH($E7,QBTeams,0)),0))} -> 0 | O7: {=IF($B7="","",IFERROR(MEDIAN(-RestCapPts,RestCapPts,RestPerDay*(INDEX(SchedZone,MATCH($A7,SchedSeq,0),MAP!$B$16)-INDEX(SchedZone,MATCH($A7,SchedSeq,0),MAP!$B$15))),0))} -> 0 | P7: =IF($B7="","",SUMIFS(AdjSpread,AdjGameID,$B7,AdjTeam,$F7,AdjActive,1)-SUMIFS(AdjSpread,AdjGameID,$B7,AdjTeam,$E7,AdjActive,1)) -> 0 | Q7: =IF($L7="","",ROUND($L7+$M7+$N7+$O7+$P7,2)) -> -0.56 | S7: =IF(AND($R7="",$Q7=""),"",IF($R7<>"",$R7,$Q7)) -> -0.56 | T7: =IF($S7="","",IF(ABS($S7)<0.05,"PK",IF($S7>0,$F7&" "&TEXT(-$S7,"+0.0;-0.0"),$E7&" "&TEXT($S7,"+0.0;-0.0")))) -> CHI -0.6 | U7: {=IF($B7="","",IFERROR(INDEX(MktHomeSpread,MATCH($B7,MktGameID,0)),""))} | V7: =IF(OR($S7="",$U7=""),"",ROUND($S7+$U7,2)) | W7: =IF($V7="","",ABS($V7)) | X7: =IF($V7="","",IF($V7>0,$F7&" "&TEXT($U7,"+0.0;-0.0;""PK"""),$E7&" "&TEXT(-$U7,"+0.0;-0.0;""PK"""))) | Y7: {=IF($B7="","",IF((IF(AND(IFERROR(INDEX(RatGP,MATCH($E7,RatTeams,0)),0)>=MinGamesTrust,IFERROR(INDEX(RatGP,MATCH($F7,RatTeams,0)),0)>=MinGamesTrust),1,0)+IF($AP7="READY",1,0)+IF(AND(IFERROR(INDEX(RatMode,MATCH($E7,RatTeams,0)),"")="ENHANCED",IFERROR(INDEX(RatMode,MATCH($F7,RatTeams,0)),"")="ENHANCED"),1,0)+IF($AO7="",1,0)+IF(IFERROR(INDEX(MktStale,MATCH($B7,MktGameID,0)),"")<>"STALE",1,0))>=5,"High",IF((IF(AND(IFERROR(INDEX(RatGP,MATCH($E7,RatTeams,0)),0)>=MinGamesTrust,IFERROR(INDEX(RatGP,MATCH($F7,RatTeams,0)),0)>=MinGamesTrust),1,0)+IF($AP7="READY",1,0)+IF(AND(IFERROR(INDEX(RatMode,MATCH($E7,RatTeams,0)),"")="ENHANCED",IFERROR(INDEX(RatMode,MATCH($F7,RatTeams,0)),"")="ENHANCED"),1,0)+IF($AO7="",1,0)+IF(IFERROR(INDEX(MktStale,MATCH($B7,MktGameID,0)),"")<>"STALE",1,0))>=4,"Medium","Low")))} -> Low | Z7: =IF(OR($B7="",$V7=""),"",IF(LEFT($AP7,7)="BLOCKED","",IF(AND($W7>=BetATS,$Y7<>"Low"),IF(AND(EnableBetLabels="Y",$Y7="High",$AP7="READY",ABS(IF($P7="",0,$P7))<=AdjCap),"BET","STRONG INVESTIGATE"),IF($W7>=InvATS,"INVESTIGATE",IF(AND($W7>=LeanATS,$Y7<>"Low"),"LEAN",""))))) | AA7: {=IF($B7="","",IFERROR(ROUND(((1-TotRegress)*0.5*(INDEX(CalcOffPl,MATCH($E7,CalcTeams,0))+INDEX(CalcDefPl,MATCH($F7,CalcTeams,0)))+TotRegress*LeaguePlays)*(INDEX(CalcOffAdj,MATCH($E7,CalcTeams,0))+INDEX(CalcDefAdj,MATCH($F7,CalcTeams,0))-LeaguePPP)+DstPts,2),""))} -> 0 | AB7: {=IF($B7="","",IFERROR(ROUND(((1-TotRegress)*0.5*(INDEX(CalcOffPl,MATCH($F7,CalcTeams,0))+INDEX(CalcDefPl,MATCH($E7,CalcTeams,0)))+TotRegress*LeaguePlays)*(INDEX(CalcOffAdj,MATCH($F7,CalcTeams,0))+INDEX(CalcDefAdj,MATCH($E7,CalcTeams,0))-LeaguePPP)+DstPts,2),""))} -> 0 | AC7: {=IF($B7="","",IFERROR(INDEX(QBTotEff,MATCH($F7,QBTeams,0)),0)+IFERROR(INDEX(QBTotEff,MATCH($E7,QBTeams,0)),0))} -> 0 | AD7: =IF($B7="","",SUMIFS(AdjTot,AdjGameID,$B7,AdjActive,1)) -> 0 | AE7: =IF(OR($AA7="",$AB7=""),"",ROUND($AA7+$AB7+$AC7+$AD7,2)) -> 0 | AG7: =IF(AND($AF7="",$AE7=""),"",IF($AF7<>"",$AF7,$AE7)) -> 0 | AH7: {=IF($B7="","",IFERROR(INDEX(MktTotal,MATCH($B7,MktGameID,0)),""))} | AI7: =IF(OR($AG7="",$AH7=""),"",ROUND($AG7-$AH7,2)) | AJ7: =IF($AI7="","",ABS($AI7)) | AK7: =IF($AI7="","",IF($AI7>0.05,"OVER",IF($AI7<-0.05,"UNDER","—"))) | AL7: {=IF($B7="","",IF((IF(AND(IFERROR(INDEX(RatGP,MATCH($E7,RatTeams,0)),0)>=MinGamesTrust,IFERROR(INDEX(RatGP,MATCH($F7,RatTeams,0)),0)>=MinGamesTrust),1,0)+IF($AP7="READY",1,0)+IF($AO7="",1,0)+IF(IFERROR(INDEX(MktStale,MATCH($B7,MktGameID,0)),"")<>"STALE",1,0)+IF(ABS(IF($AD7="",0,$AD7))<=AdjCap,1,0))>=5,"High",IF((IF(AND(IFERROR(INDEX(RatGP,MATCH($E7,RatTeams,0)),0)>=MinGamesTrust,IFERROR(INDEX(RatGP,MATCH($F7,RatTeams,0)),0)>=MinGamesTrust),1,0)+IF($AP7="READY",1,0)+IF($AO7="",1,0)+IF(IFERROR(INDEX(MktStale,MATCH($B7,MktGameID,0)),"")<>"STALE",1,0)+IF(ABS(IF($AD7="",0,$AD7))<=AdjCap,1,0))>=4,"Medium","Low")))} -> Medium | AM7: =IF(OR($B7="",$AI7=""),"",IF(LEFT($AP7,7)="BLOCKED","",IF(AND($AJ7>=BetTot,$AL7<>"Low"),IF(AND(EnableBetLabels="Y",$AL7="High",$AP7="READY"),"BET ","STRONG INVESTIGATE ")&$AK7,IF($AJ7>=InvTot,"INVESTIGATE "&$AK7,IF(AND($AJ7>=LeanTot,$AL7<>"Low"),"LEAN "&$AK7,""))))) | AN7: =IF($AG7="","","BET OVER at ≤ "&TEXT($AG7-BetTot,"0.0")&" | BET UNDER at ≥ "&TEXT($AG7+BetTot,"0.0")) -> BET OVER at ≤ -3.0 | BET UNDER at ≥ 3.0 | AO7: {=IF($B7="","",IF(OR(IFERROR(INDEX(QBFlag,MATCH($F7,QBTeams,0)),1)=1,IFERROR(INDEX(QBFlag,MATCH($E7,QBTeams,0)),1)=1),"QB UNCERTAIN",""))} | AP7: {=IF($B7="","",IFERROR(INDEX(DQStatus,MATCH($B7,DQGameID,0)),"BLOCKED — DQ ROW NOT FOUND"))} -> READY | AQ7: {=IF($B7="","",IF(LEFT($AP7,7)="BLOCKED",IF($AP7="BLOCKED","BLOCKED — see DATA QUALITY",$AP7),IF(AND($U7="",$AH7=""),"PENDING BOTH",IF($U7="","PENDING SPREAD",IF($AH7="","PENDING TOTAL",IF(IFERROR(INDEX(MktStale,MATCH($B7,MktGameID,0)),"")="STALE","STALE LINE",IF($AO7<>"",$AO7,IF(OR(NOT(ISNUMBER($J7)),NOT(ISNUMBER($K7))),"DATA INCOMPLETE","READY"))))))))} -> PENDING BOTH | AR7: =IF(OR($R7<>"",$AF7<>""),"OVERRIDE","") | AS7: {=IF(OR($B7="",$C7<>CurrentWeek),"",ROUND(25*MIN(1,IF($W7="",0,$W7)/5)+20*IF($AP7="READY",1,0)+20*IF($AO7="",1,0)+15*IF(IFERROR(INDEX(MktStale,MATCH($B7,MktGameID,0)),"x")="OK",1,0)+10*MAX(0,1-ABS(IF($P7="",0,$P7))/AdjCap)+10*IF(AND($Z7<>"",$AM7<>""),1,0),0))} -> 50 | AT7: =IF($AS7="","",RANK($AS7,$AS$5:$AS$304,0)) -> 1
